Workbook
Name JR_PAGE_ANCHOR_0_1: #REF!

Sheet 办事处汇总
A1: 西北大区服务收入统计7.28-8.9
A2: 办事处 | B2: 清洗保养 | C2: 延保服务 | D2: 止回阀 | E2: 装饰罩 | F2: 清洁耗材 | G2: 水/气路金属软管 | H2: 其他产品线专用 | I2: 排烟出风管 | J2: 其他水路辅材 | K2: 其他气路辅材 | L2: 橱柜类辅材 | M2: 水气路通用辅材 | N2: 燃气管快速接头 | O2: 工具 | P2: 合计 | Q2: 7月任务 | R2: 服务收入完成进度 | S2: 120% 每天完成 | T2: 三大爆品合计 | U2: 三大爆品任务 | V2: 三大爆品 完成率
A3: 包头办事处 | B3: =SUMIFS(CSM服务项目!Y:Y,CSM服务项目!Q:Q,$B$2,CSM服务项目!B:B,A3) -> 1453 | C3: =SUMIFS(CSM服务项目!Y:Y,CSM服务项目!Q:Q,$C$2,CSM服务项目!B:B,A3) -> 343.5 | D3: =SUMIFS(CSM配件!AB:AB,CSM配件!R:R,$D$2,CSM配件!C:C,A3) -> 3760 | E3: =SUMIFS(CSM配件!AB:AB,CSM配件!R:R,$E$2,CSM配件!C:C,A3) -> 0 | F3: =SUMIFS(CSM配件!AB:AB,CSM配件!R:R,$F$2,CSM配件!C:C,A3)+SUMIFS(WMS网点买断配件明细!I:I,WMS网点买断配件明细!K:K,$F$2,WMS网点买断配件明细!B:B,A3) -> 2528 | G3: =SUMIFS(CSM配件!AB:AB,CSM配件!R:R,$G$2,CSM配件!C:C,A3)+SUMIFS(WMS网点买断配件明细!I:I,WMS网点买断配件明细!K:K,$G$2,WMS网点买断配件明细!B:B,A3) -> 408.21 | H3: =SUMIFS(CSM配件!AB:AB,CSM配件!R:R,$H$2,CSM配件!C:C,A3)+SUMIFS(WMS网点买断配件明细!I:I,WMS网点买断配件明细!K:K,$H$2,WMS网点买断配件明细!B:B,A3) -> 4249 | I3: =SUMIFS(CSM配件!AB:AB,CSM配件!R:R,$I$2,CSM配件!C:C,A3)+SUMIFS(WMS网点买断配件明细!I:I,WMS网点买断配件明细!K:K,$I$2,WMS网点买断配件明细!B:B,A3) -> 372 | J3: =SUMIFS(CSM配件!AB:AB,CSM配件!R:R,$J$2,CSM配件!C:C,A3)+SUMIFS(WMS网点买断配件明细!I:I,WMS网点买断配件明细!K:K,$J$2,WMS网点买断配件明细!B:B,A3) -> 196 | K3: =SUMIFS(CSM配件!AB:AB,CSM配件!R:R,$K$2,CSM配件!C:C,A3)+SUMIFS(WMS网点买断配件明细!I:I,WMS网点买断配件明细!K:K,$K$2,WMS网点买断配件明细!B:B,A3) -> 0 | L3: =SUMIFS(CSM配件!AB:AB,CSM配件!R:R,$L$2,CSM配件!C:C,A3)+SUMIFS(WMS网点买断配件明细!I:I,WMS网点买断配件明细!K:K,$L$2,WMS网点买断配件明细!B:B,A3) -> 155 | M3: =SUMIFS(CSM配件!AB:AB,CSM配件!R:R,$M$2,CSM配件!C:C,A3)+SUMIFS(WMS网点买断配件明细!I:I,WMS网点买断配件明细!K:K,$M$2,WMS网点买断配件明细!B:B,A3) -> 0 | N3: =SUMIFS(CSM配件!AB:AB,CSM配件!R:R,$N$2,CSM配件!C:C,A3)+SUMIFS(WMS网点买断配件明细!I:I,WMS网点买断配件明细!K:K,$N$2,WMS网点买断配件明细!B:B,A3) -> 44.4 | O3: =SUMIFS(CSM配件!AB:AB,CSM配件!R:R,$O$2,CSM配件!C:C,A3)+SUMIFS(WMS网点买断配件明细!I:I,WMS网点买断配件明细!K:K,$O$2,WMS网点买断配件明细!B:B,A3) -> 0 | P3: =SUM(B3:O3) -> 13509.11 | Q3: 35100 | R3: =P3/Q3 -> 0.38487493 | S3: =(Q3*1.2-P3)/19 -> 1505.8363 | T3: =B3+C3+F3 -> 4324.5 | U3: 12600 | V3: =T3/U3 -> 0.34321429
A4: 呼和浩特办事处 | B4: =SUMIFS(CSM服务项目!Y:Y,CSM服务项目!Q:Q,$B$2,CSM服务项目!B:B,A4) -> 2344 | C4: =SUMIFS(CSM服务项目!Y:Y,CSM服务项目!Q:Q,$C$2,CSM服务项目!B:B,A4) -> 0 | D4: =SUMIFS(CSM配件!AB:AB,CSM配件!R:R,$D$2,CSM配件!C:C,A4) -> 2880 | E4: =SUMIFS(CSM配件!AB:AB,CSM配件!R:R,$E$2,CSM配件!C:C,A4) -> 1127 | F4: =SUMIFS(CSM配件!AB:AB,CSM配件!R:R,$F$2,CSM配件!C:C,A4)+SUMIFS(WMS网点买断配件明细!I:I,WMS网点买断配件明细!K:K,$F$2,WMS网点买断配件明细!B:B,A4) -> 465 | G4: =SUMIFS(CSM配件!AB:AB,CSM配件!R:R,$G$2,CSM配件!C:C,A4)+SUMIFS(WMS网点买断配件明细!I:I,WMS网点买断配件明细!K:K,$G$2,WMS网点买断配件明细!B:B,A4) -> 662.97 | H4: =SUMIFS(CSM配件!AB:AB,CSM配件!R:R,$H$2,CSM配件!C:C,A4)+SUMIFS(WMS网点买断配件明细!I:I,WMS网点买断配件明细!K:K,$H$2,WMS网点买断配件明细!B:B,A4) -> 3732.5 | I4: =SUMIFS(CSM配件!AB:AB,CSM配件!R:R,$I$2,CSM配件!C:C,A4)+SUMIFS(WMS网点买断配件明细!I:I,WMS网点买断配件明细!K:K,$I$2,WMS网点买断配件明细!B:B,A4) -> 860.5 | J4: =SUMIFS(CSM配件!AB:AB,CSM配件!R:R,$J$2,CSM配件!C:C,A4)+SUMIFS(WMS网点买断配件明细!I:I,WMS网点买断配件明细!K:K,$J$2,WMS网点买断配件明细!B:B,A4) -> 1588 | K4: =SUMIFS(CSM配件!AB:AB,CSM配件!R:R,$K$2,CSM配件!C:C,A4)+SUMIFS(WMS网点买断配件明细!I:I,WMS网点买断配件明细!K:K,$K$2,WMS网点买断配件明细!B:B,A4) -> 0 | L4: =SUMIFS(CSM配件!AB:AB,CSM配件!R:R,$L$2,CSM配件!C:C,A4)+SUMIFS(WMS网点买断配件明细!I:I,WMS网点买断配件明细!K:K,$L$2,WMS网点买断配件明细!B:B,A4) -> 52.5 | M4: =SUMIFS(CSM配件!AB:AB,CSM配件!R:R,$M$2,CSM配件!C:C,A4)+SUMIFS(WMS网点买断配件明细!I:I,WMS网点买断配件明细!K:K,$M$2,WMS网点买断配件明细!B:B,A4) -> 0 | N4: =SUMIFS(CSM配件!AB:AB,CSM配件!R:R,$N$2,CSM配件!C:C,A4)+SUMIFS(WMS网点买断配件明细!I:I,WMS网点买断配件明细!K:K,$N$2,WMS网点买断配件明细!B:B,A4) -> 0 | O4: =SUMIFS(CSM配件!AB:AB,CSM配件!R:R,$O$2,CSM配件!C:C,A4)+SUMIFS(WMS网点买断配件明细!I:I,WMS网点买断配件明细!K:K,$O$2,WMS网点买断配件明细!B:B,A4) -> 0 | P4: =SUM(B4:O4) -> 13712.47 | Q4: 32400 | R4: =P4/Q4 -> 0.42322438 | S4: =(Q4*1.2-P4)/19 -> 1324.6068 | T4: =B4+C4+F4 -> 2809 | U4: 11700 | V4: =T4/U4 -> 0.24008547
A5: 兰州办事处 | B5: =SUMIFS(CSM服务项目!Y:Y,CSM服务项目!Q:Q,$B$2,CSM服务项目!B:B,A5) -> 4112 | C5: =SUMIFS(CSM服务项目!Y:Y,CSM服务项目!Q:Q,$C$2,CSM服务项目!B:B,A5) -> 4442.6 | D5: =SUMIFS(CSM配件!AB:AB,CSM配件!R:R,$D$2,CSM配件!C:C,A5) -> 8600 | E5: =SUMIFS(CSM配件!AB:AB,CSM配件!R:R,$E$2,CSM配件!C:C,A5) -> 1405.6 | F5: =SUMIFS(CSM配件!AB:AB,CSM配件!R:R,$F$2,CSM配件!C:C,A5)+SUMIFS(WMS网点买断配件明细!I:I,WMS网点买断配件明细!K:K,$F$2,WMS网点买断配件明细!B:B,A5) -> 675 | G5: =SUMIFS(CSM配件!AB:AB,CSM配件!R:R,$G$2,CSM配件!C:C,A5)+SUMIFS(WMS网点买断配件明细!I:I,WMS网点买断配件明细!K:K,$G$2,WMS网点买断配件明细!B:B,A5) -> 7430.7 | H5: =SUMIFS(CSM配件!AB:AB,CSM配件!R:R,$H$2,CSM配件!C:C,A5)+SUMIFS(WMS网点买断配件明细!I:I,WMS网点买断配件明细!K:K,$H$2,WMS网点买断配件明细!B:B,A5) -> 3608 | I5: =SUMIFS(CSM配件!AB:AB,CSM配件!R:R,$I$2,CSM配件!C:C,A5)+SUMIFS(WMS网点买断配件明细!I:I,WMS网点买断配件明细!K:K,$I$2,WMS网点买断配件明细!B:B,A5) -> 1184 | J5: =SUMIFS(CSM配件!AB:AB,CSM配件!R:R,$J$2,CSM配件!C:C,A5)+SUMIFS(WMS网点买断配件明细!I:I,WMS网点买断配件明细!K:K,$J$2,WMS网点买断配件明细!B:B,A5) -> 84 | K5: =SUMIFS(CSM配件!AB:AB,CSM配件!R:R,$K$2,CSM配件!C:C,A5)+SUMIFS(WMS网点买断配件明细!I:I,WMS网点买断配件明细!K:K,$K$2,WMS网点买断配件明细!B:B,A5) -> 0 | L5: =SUMIFS(CSM配件!AB:AB,CSM配件!R:R,$L$2,CSM配件!C:C,A5)+SUMIFS(WMS网点买断配件明细!I:I,WMS网点买断配件明细!K:K,$L$2,WMS网点买断配件明细!B:B,A5) -> 112 | M5: =SUMIFS(CSM配件!AB:AB,CSM配件!R:R,$M$2,CSM配件!C:C,A5)+SUMIFS(WMS网点买断配件明细!I:I,WMS网点买断配件明细!K:K,$M$2,WMS网点买断配件明细!B:B,A5) -> 0 | N5: =SUMIFS(CSM配件!AB:AB,CSM配件!R:R,$N$2,CSM配件!C:C,A5)+SUMIFS(WMS网点买断配件明细!I:I,WMS网点买断配件明细!K:K,$N$2,WMS网点买断配件明细!B:B,A5) -> 1004 | O5: =SUMIFS(CSM配件!AB:AB,CSM配件!R:R,$O$2,CSM配件!C:C,A5)+SUMIFS(WMS网点买断配件明细!I:I,WMS网点买断配件明细!K:K,$O$2,WMS网点买断配件明细!B:B,A5) -> 0 | P5: =SUM(B5:O5) -> 32657.9 | Q5: 83700 | R5: =P5/Q5 -> 0.39017802 | S5: =(Q5*1.2-P5)/19 -> 3567.4789 | T5: =B5+C5+F5 -> 9229.6 | U5: 23400 | V5: =T5/U5 -> 0.39442735
A6: 宁夏办事处 | B6: =SUMIFS(CSM服务项目!Y:Y,CSM服务项目!Q:Q,$B$2,CSM服务项目!B:B,A6) -> 7187 | C6: =SUMIFS(CSM服务项目!Y:Y,CSM服务项目!Q:Q,$C$2,CSM服务项目!B:B,A6) -> 7509.7 | D6: =SUMIFS(CSM配件!AB:AB,CSM配件!R:R,$D$2,CSM配件!C:C,A6) -> 14800 | E6: =SUMIFS(CSM配件!AB:AB,CSM配件!R:R,$E$2,CSM配件!C:C,A6) -> 441 | F6: =SUMIFS(CSM配件!AB:AB,CSM配件!R:R,$F$2,CSM配件!C:C,A6)+SUMIFS(WMS网点买断配件明细!I:I,WMS网点买断配件明细!K:K,$F$2,WMS网点买断配件明细!B:B,A6) -> 6065 | G6: =SUMIFS(CSM配件!AB:AB,CSM配件!R:R,$G$2,CSM配件!C:C,A6)+SUMIFS(WMS网点买断配件明细!I:I,WMS网点买断配件明细!K:K,$G$2,WMS网点买断配件明细!B:B,A6) -> 2577.22 | H6: =SUMIFS(CSM配件!AB:AB,CSM配件!R:R,$H$2,CSM配件!C:C,A6)+SUMIFS(WMS网点买断配件明细!I:I,WMS网点买断配件明细!K:K,$H$2,WMS网点买断配件明细!B:B,A6) -> 4460.4 | I6: =SUMIFS(CSM配件!AB:AB,CSM配件!R:R,$I$2,CSM配件!C:C,A6)+SUMIFS(WMS网点买断配件明细!I:I,WMS网点买断配件明细!K:K,$I$2,WMS网点买断配件明细!B:B,A6) -> 2090.5 | J6: =SUMIFS(CSM配件!AB:AB,CSM配件!R:R,$J$2,CSM配件!C:C,A6)+SUMIFS(WMS网点买断配件明细!I:I,WMS网点买断配件明细!K:K,$J$2,WMS网点买断配件明细!B:B,A6) -> 1539 | K6: =SUMIFS(CSM配件!AB:AB,CSM配件!R:R,$K$2,CSM配件!C:C,A6)+SUMIFS(WMS网点买断配件明细!I:I,WMS网点买断配件明细!K:K,$K$2,WMS网点买断配件明细!B:B,A6) -> 0 | L6: =SUMIFS(CSM配件!AB:AB,CSM配件!R:R,$L$2,CSM配件!C:C,A6)+SUMIFS(WMS网点买断配件明细!I:I,WMS网点买断配件明细!K:K,$L$2,WMS网点买断配件明细!B:B,A6) -> 94.5 | M6: =SUMIFS(CSM配件!AB:AB,CSM配件!R:R,$M$2,CSM配件!C:C,A6)+SUMIFS(WMS网点买断配件明细!I:I,WMS网点买断配件明细!K:K,$M$2,WMS网点买断配件明细!B:B,A6) -> 0 | N6: =SUMIFS(CSM配件!AB:AB,CSM配件!R:R,$N$2,CSM配件!C:C,A6)+SUMIFS(WMS网点买断配件明细!I:I,WMS网点买断配件明细!K:K,$N$2,WMS网点买断配件明细!B:B,A6) -> 133.2 | O6: =SUMIFS(CSM配件!AB:AB,CSM配件!R:R,$O$2,CSM配件!C:C,A6)+SUMIFS(WMS网点买断配件明细!I:I,WMS网点买断配件明细!K:K,$O$2,WMS网点买断配件明细!B:B,A6) -> 0 | P6: =SUM(B6:O6) -> 46897.52 | Q6: 111600 | R6: =P6/Q6 -> 0.42022867 | S6: =(Q6*1.2-P6)/19 -> 4580.1305 | T6: =B6+C6+F6 -> 20761.7 | U6: 35100 | V6: =T6/U6 -> 0.59150142
A7: 西宁办事处 | B7: =SUMIFS(CSM服务项目!Y:Y,CSM服务项目!Q:Q,$B$2,CSM服务项目!B:B,A7) -> 150 | C7: =SUMIFS(CSM服务项目!Y:Y,CSM服务项目!Q:Q,$C$2,CSM服务项目!B:B,A7) -> 2633.5 | D7: =SUMIFS(CSM配件!AB:AB,CSM配件!R:R,$D$2,CSM配件!C:C,A7) -> 900 | E7: =SUMIFS(CSM配件!AB:AB,CSM配件!R:R,$E$2,CSM配件!C:C,A7) -> 0 | F7: =SUMIFS(CSM配件!AB:AB,CSM配件!R:R,$F$2,CSM配件!C:C,A7)+SUMIFS(WMS网点买断配件明细!I:I,WMS网点买断配件明细!K:K,$F$2,WMS网点买断配件明细!B:B,A7) -> 132 | G7: =SUMIFS(CSM配件!AB:AB,CSM配件!R:R,$G$2,CSM配件!C:C,A7)+SUMIFS(WMS网点买断配件明细!I:I,WMS网点买断配件明细!K:K,$G$2,WMS网点买断配件明细!B:B,A7) -> 0 | H7: =SUMIFS(CSM配件!AB:AB,CSM配件!R:R,$H$2,CSM配件!C:C,A7)+SUMIFS(WMS网点买断配件明细!I:I,WMS网点买断配件明细!K:K,$H$2,WMS网点买断配件明细!B:B,A7) -> 1126.5 | I7: =SUMIFS(CSM配件!AB:AB,CSM配件!R:R,$I$2,CSM配件!C:C,A7)+SUMIFS(WMS网点买断配件明细!I:I,WMS网点买断配件明细!K:K,$I$2,WMS网点买断配件明细!B:B,A7) -> 591.5 | J7: =SUMIFS(CSM配件!AB:AB,CSM配件!R:R,$J$2,CSM配件!C:C,A7)+SUMIFS(WMS网点买断配件明细!I:I,WMS网点买断配件明细!K:K,$J$2,WMS网点买断配件明细!B:B,A7) -> 0 | K7: =SUMIFS(CSM配件!AB:AB,CSM配件!R:R,$K$2,CSM配件!C:C,A7)+SUMIFS(WMS网点买断配件明细!I:I,WMS网点买断配件明细!K:K,$K$2,WMS网点买断配件明细!B:B,A7) -> 0 | L7: =SUMIFS(CSM配件!AB:AB,CSM配件!R:R,$L$2,CSM配件!C:C,A7)+SUMIFS(WMS网点买断配件明细!I:I,WMS网点买断配件明细!K:K,$L$2,WMS网点买断配件明细!B:B,A7) -> 0 | M7: =SUMIFS(CSM配件!AB:AB,CSM配件!R:R,$M$2,CSM配件!C:C,A7)+SUMIFS(WMS网点买断配件明细!I:I,WMS网点买断配件明细!K:K,$M$2,WMS网点买断配件明细!B:B,A7) -> 0 | N7: =SUMIFS(CSM配件!AB:AB,CSM配件!R:R,$N$2,CSM配件!C:C,A7)+SUMIFS(WMS网点买断配件明细!I:I,WMS网点买断配件明细!K:K,$N$2,WMS网点买断配件明细!B:B,A7) -> 0 | O7: =SUMIFS(CSM配件!AB:AB,CSM配件!R:R,$O$2,CSM配件!C:C,A7)+SUMIFS(WMS网点买断配件明细!I:I,WMS网点买断配件明细!K:K,$O$2,WMS网点买断配件明细!B:B,A7) -> 0 | P7: =SUM(B7:O7) -> 5533.5 | Q7: 14400 | R7: =P7/Q7 -> 0.38427083 | S7: =(Q7*1.2-P7)/19 -> 618.23684 | T7: =B7+C7+F7 -> 2915.5 | U7: 4500 | V7: =T7/U7 -> 0.64788889
A8: 新疆办事处 | B8: =SUMIFS(CSM服务项目!Y:Y,CSM服务项目!Q:Q,$B$2,CSM服务项目!B:B,A8) -> 19558 | C8: =SUMIFS(CSM服务项目!Y:Y,CSM服务项目!Q:Q,$C$2,CSM服务项目!B:B,A8) -> 7236.4 | D8: =SUMIFS(CSM配件!AB:AB,CSM配件!R:R,$D$2,CSM配件!C:C,A8) -> 22500 | E8: =SUMIFS(CSM配件!AB:AB,CSM配件!R:R,$E$2,CSM配件!C:C,A8) -> 411.6 | F8: =SUMIFS(CSM配件!AB:AB,CSM配件!R:R,$F$2,CSM配件!C:C,A8)+SUMIFS(WMS网点买断配件明细!I:I,WMS网点买断配件明细!K:K,$F$2,WMS网点买断配件明细!B:B,A8) -> 3875 | G8: =SUMIFS(CSM配件!AB:AB,CSM配件!R:R,$G$2,CSM配件!C:C,A8)+SUMIFS(WMS网点买断配件明细!I:I,WMS网点买断配件明细!K:K,$G$2,WMS网点买断配件明细!B:B,A8) -> 7755.99 | H8: =SUMIFS(CSM配件!AB:AB,CSM配件!R:R,$H$2,CSM配件!C:C,A8)+SUMIFS(WMS网点买断配件明细!I:I,WMS网点买断配件明细!K:K,$H$2,WMS网点买断配件明细!B:B,A8) -> 8555 | I8: =SUMIFS(CSM配件!AB:AB,CSM配件!R:R,$I$2,CSM配件!C:C,A8)+SUMIFS(WMS网点买断配件明细!I:I,WMS网点买断配件明细!K:K,$I$2,WMS网点买断配件明细!B:B,A8) -> 5281 | J8: =SUMIFS(CSM配件!AB:AB,CSM配件!R:R,$J$2,CSM配件!C:C,A8)+SUMIFS(WMS网点买断配件明细!I:I,WMS网点买断配件明细!K:K,$J$2,WMS网点买断配件明细!B:B,A8) -> 1750 | K8: =SUMIFS(CSM配件!AB:AB,CSM配件!R:R,$K$2,CSM配件!C:C,A8)+SUMIFS(WMS网点买断配件明细!I:I,WMS网点买断配件明细!K:K,$K$2,WMS网点买断配件明细!B:B,A8) -> 0 | L8: =SUMIFS(CSM配件!AB:AB,CSM配件!R:R,$L$2,CSM配件!C:C,A8)+SUMIFS(WMS网点买断配件明细!I:I,WMS网点买断配件明细!K:K,$L$2,WMS网点买断配件明细!B:B,A8) -> 224 | M8: =SUMIFS(CSM配件!AB:AB,CSM配件!R:R,$M$2,CSM配件!C:C,A8)+SUMIFS(WMS网点买断配件明细!I:I,WMS网点买断配件明细!K:K,$M$2,WMS网点买断配件明细!B:B,A8) -> 0 | N8: =SUMIFS(CSM配件!AB:AB,CSM配件!R:R,$N$2,CSM配件!C:C,A8)+SUMIFS(WMS网点买断配件明细!I:I,WMS网点买断配件明细!K:K,$N$2,WMS网点买断配件明细!B:B,A8) -> 2461 | O8: =SUMIFS(CSM配件!AB:AB,CSM配件!R:R,$O$2,CSM配件!C:C,A8)+SUMIFS(WMS网点买断配件明细!I:I,WMS网点买断配件明细!K:K,$O$2,WMS网点买断配件明细!B:B,A8) -> 0 | P8: =SUM(B8:O8) -> 79607.99 | Q8: 168300 | R8: =P8/Q8 -> 0.47301242 | S8: =(Q8*1.2-P8)/19 -> 6439.5795 | T8: =B8+C8+F8 -> 30669.4 | U8: 48600 | V8: =T8/U8 -> 0.63105761
A9: 西北大区部 | B9: =SUM(B3:B8) -> 34804 | C9: =SUM(C3:C8) -> 22165.7 | D9: =SUM(D3:D8) -> 53440 | E9: =SUM(E3:E8) -> 3385.2 | F9: =SUM(F3:F8) -> 13740 | G9: =SUM(G3:G8) -> 18835.09 | H9: =SUM(H3:H8) -> 25731.4 | I9: =SUM(I3:I8) -> 10379.5 | ... Q9: =SUM(Q3:Q8) -> 445500 | R9: =P9/Q9 -> 0.43079347 | S9: =(Q9*1.2-P9)/19 -> 18035.869 | T9: =SUM(T3:T8) -> 70709.7 | U9: =SUM(U3:U8) -> 135900 | V9: =T9/U9 -> 0.52030684

Sheet 服务产品+三大爆品
A1: 服务产品完成情况 | J1: 三大爆品完成情况
A2: 办事处 | B2: 1-7月 完成 | C2: 8月份 达成 | D2: 8月份 目标 | E2: 8月 完成率 | F2: 累计达成 | G2: 全年目标 | H2: 距离120%差值 | I2: 年度完 成进度 | J2: 1-7月 完成 | K2: 8月份 达成 | L2: 8月份 目标 | M2: 8月 完成率 | N2: 累计达成 | O2: 全年目标 | P2: 年度完 成进度
A3: 包头办事处 | B3: =19.564417+3.235077 -> 22.799494 | C3: 0 | D3: 3.51 | E3: =C3/D3 -> 0 | F3: =B3+C3 -> 22.799494 | G3: 39 | H3: =G3*1.2-F3 -> 24.000506 | I3: =F3/G3 -> 0.58460241 | J3: =8.1701+0.9251 -> 9.0952 | K3: 0 | L3: 1.26 | M3: =K3/L3 -> 0 | N3: =J3+K3 -> 9.0952 | O3: 14 | P3: =N3/O3 -> 0.64965714
A4: 呼和浩特办事处 | B4: =18.522305+3.704106 -> 22.226411 | C4: 0 | D4: 3.24 | E4: =C4/D4 -> 0 | F4: =B4+C4 -> 22.226411 | G4: 36 | H4: =G4*1.2-F4 -> 20.973589 | I4: =F4/G4 -> 0.61740031 | J4: =6.52498+0.71624 -> 7.24122 | K4: 0 | L4: 1.17 | M4: =K4/L4 -> 0 | N4: =J4+K4 -> 7.24122 | O4: 13 | P4: =N4/O4 -> 0.55701692
A5: 兰州办事处 | B5: =39.291882+6.801145 -> 46.093027 | C5: 0 | D5: 8.37 | E5: =C5/D5 -> 0 | F5: =B5+C5 -> 46.093027 | G5: 93 | H5: =G5*1.2-F5 -> 65.506973 | I5: =F5/G5 -> 0.49562395 | J5: =12.9608+1.66925 -> 14.63005 | K5: 0 | L5: 2.34 | M5: =K5/L5 -> 0 | N5: =J5+K5 -> 14.63005 | O5: 26 | P5: =N5/O5 -> 0.56269423
A6: 宁夏办事处 | B6: =64.731382+10.771978 -> 75.50336 | C6: 0 | D6: 11.16 | E6: =C6/D6 -> 0 | F6: =B6+C6 -> 75.50336 | G6: 124 | H6: =G6*1.2-F6 -> 73.29664 | I6: =F6/G6 -> 0.60889806 | J6: =27.88965+4.74917 -> 32.63882 | K6: 0 | L6: 3.51 | M6: =K6/L6 -> 0 | N6: =J6+K6 -> 32.63882 | O6: 39 | P6: =N6/O6 -> 0.83689282
A7: 西宁办事处 | B7: =6.551844+1.596426 -> 8.14827 | C7: 0 | D7: 1.44 | E7: =C7/D7 -> 0 | F7: =B7+C7 -> 8.14827 | G7: 16 | H7: =G7*1.2-F7 -> 11.05173 | I7: =F7/G7 -> 0.50926688 | J7: =1.90205+0.49436 -> 2.39641 | K7: 0 | L7: 0.45 | M7: =K7/L7 -> 0 | N7: =J7+K7 -> 2.39641 | O7: 5 | P7: =N7/O7 -> 0.479282
A8: 新疆办事处 | B8: =84.612167+17.218253 -> 101.83042 | C8: 0 | D8: 16.83 | E8: =C8/D8 -> 0 | F8: =B8+C8 -> 101.83042 | G8: 187 | H8: =G8*1.2-F8 -> 122.56958 | I8: =F8/G8 -> 0.5445477 | J8: =27.58084+5.16552 -> 32.74636 | K8: 0 | L8: 4.86 | M8: =K8/L8 -> 0 | N8: =J8+K8 -> 32.74636 | O8: 54 | P8: =N8/O8 -> 0.60641407
A9: 小计 | B9: =SUM(B3:B8) -> 276.60098 | C9: =SUM(C3:C8) -> 0 | D9: =SUM(D3:D8) -> 44.55 | E9: =C9/D9 -> 0 | F9: =SUM(F3:F8) -> 276.60098 | G9: =SUM(G3:G8) -> 495 | H9: =G9*1.2-F9 -> 317.39902 | I9: =F9/G9 -> 0.55878986 | J9: =SUM(J3:J8) -> 98.74806 | K9: =SUM(K3:K8) -> 0 | L9: =SUM(L3:L8) -> 13.59 | M9: =K9/L9 -> 0 | N9: =SUM(N3:N8) -> 98.74806 | O9: =SUM(O3:O8) -> 151 | P9: =N9/O9 -> 0.65396066

Sheet 服务产品3+1
A1: 服务产品3+1
A2: 办事处 | B2: 清洗保养 | F2: 延保服务 | J2: 清洁耗材 | N2: 止回阀
B3: 46235 | C3: 45870 | D3: 差值 | E3: 同比 | F3: 46235 | G3: 45870 | H3: 差值 | I3: 同比 | J3: 46235 | K3: 45870 | L3: 差值 | M3: 同比 | N3: 46235 | O3: 46235 | P3: 差值 | Q3: 同比
A4: 包头办事处 | B4: =SUMIFS(CSM服务项目!Y:Y,CSM服务项目!Q:Q,$B$2,CSM服务项目!B:B,A4) -> 1453 | C4: 3572 | D4: =B4-C4 -> -2119 | E4: =B4/C4-1 -> -0.59322508 | F4: =SUMIFS(CSM服务项目!Y:Y,CSM服务项目!Q:Q,$F$2,CSM服务项目!B:B,A4) -> 343.5 | G4: 855.3 | H4: =F4-G4 -> -511.8 | I4: =F4/G4-1 -> -0.59838653 | J4: =SUMIFS(CSM配件!AB:AB,CSM配件!R:R,$J$2,CSM配件!C:C,A4)+SUMIFS(WMS网点买断配件明细!I:I,WMS网点买断配件明细!K:K,$J$2,WMS网点买断配件明细!B:B,A4) -> 2528 | K4: 3580 | L4: =J4-K4 -> -1052 | M4: =J4/K4-1 -> -0.29385475 | N4: =SUMIFS(CSM配件!AB:AB,CSM配件!R:R,$N$2,CSM配件!C:C,A4) -> 3760 | O4: 9460 | P4: =N4-O4 -> -5700 | Q4: =N4/O4-1 -> -0.602537
A5: 呼和浩特办事处 | B5: =SUMIFS(CSM服务项目!Y:Y,CSM服务项目!Q:Q,$B$2,CSM服务项目!B:B,A5) -> 2344 | C5: 6440 | D5: =B5-C5 -> -4096 | E5: =B5/C5-1 -> -0.63602484 | F5: =SUMIFS(CSM服务项目!Y:Y,CSM服务项目!Q:Q,$F$2,CSM服务项目!B:B,A5) -> 0 | G5: 389.3 | H5: =F5-G5 -> -389.3 | I5: =F5/G5-1 -> -1 | J5: =SUMIFS(CSM配件!AB:AB,CSM配件!R:R,$J$2,CSM配件!C:C,A5)+SUMIFS(WMS网点买断配件明细!I:I,WMS网点买断配件明细!K:K,$J$2,WMS网点买断配件明细!B:B,A5) -> 465 | K5: 1550 | L5: =J5-K5 -> -1085 | M5: =J5/K5-1 -> -0.7 | N5: =SUMIFS(CSM配件!AB:AB,CSM配件!R:R,$N$2,CSM配件!C:C,A5) -> 2880 | O5: 3740 | P5: =N5-O5 -> -860 | Q5: =N5/O5-1 -> -0.22994652
A6: 兰州办事处 | B6: =SUMIFS(CSM服务项目!Y:Y,CSM服务项目!Q:Q,$B$2,CSM服务项目!B:B,A6) -> 4112 | C6: 11413 | D6: =B6-C6 -> -7301 | E6: =B6/C6-1 -> -0.6397091 | F6: =SUMIFS(CSM服务项目!Y:Y,CSM服务项目!Q:Q,$F$2,CSM服务项目!B:B,A6) -> 4442.6 | G6: 2061 | H6: =F6-G6 -> 2381.6 | I6: =F6/G6-1 -> 1.1555556 | J6: =SUMIFS(CSM配件!AB:AB,CSM配件!R:R,$J$2,CSM配件!C:C,A6)+SUMIFS(WMS网点买断配件明细!I:I,WMS网点买断配件明细!K:K,$J$2,WMS网点买断配件明细!B:B,A6) -> 675 | K6: 886 | L6: =J6-K6 -> -211 | M6: =J6/K6-1 -> -0.23814898 | N6: =SUMIFS(CSM配件!AB:AB,CSM配件!R:R,$N$2,CSM配件!C:C,A6) -> 8600 | O6: 26500 | P6: =N6-O6 -> -17900 | Q6: =N6/O6-1 -> -0.6754717
A7: 宁夏办事处 | B7: =SUMIFS(CSM服务项目!Y:Y,CSM服务项目!Q:Q,$B$2,CSM服务项目!B:B,A7) -> 7187 | C7: 15243 | D7: =B7-C7 -> -8056 | E7: =B7/C7-1 -> -0.52850489 | F7: =SUMIFS(CSM服务项目!Y:Y,CSM服务项目!Q:Q,$F$2,CSM服务项目!B:B,A7) -> 7509.7 | G7: 1885.8 | H7: =F7-G7 -> 5623.9 | I7: =F7/G7-1 -> 2.9822357 | J7: =SUMIFS(CSM配件!AB:AB,CSM配件!R:R,$J$2,CSM配件!C:C,A7)+SUMIFS(WMS网点买断配件明细!I:I,WMS网点买断配件明细!K:K,$J$2,WMS网点买断配件明细!B:B,A7) -> 6065 | K7: 8850 | L7: =J7-K7 -> -2785 | M7: =J7/K7-1 -> -0.31468927 | N7: =SUMIFS(CSM配件!AB:AB,CSM配件!R:R,$N$2,CSM配件!C:C,A7) -> 14800 | O7: 37400 | P7: =N7-O7 -> -22600 | Q7: =N7/O7-1 -> -0.60427807
A8: 西宁办事处 | B8: =SUMIFS(CSM服务项目!Y:Y,CSM服务项目!Q:Q,$B$2,CSM服务项目!B:B,A8) -> 150 | C8: 150 | D8: =B8-C8 -> 0 | E8: =B8/C8-1 -> 0 | F8: =SUMIFS(CSM服务项目!Y:Y,CSM服务项目!Q:Q,$F$2,CSM服务项目!B:B,A8) -> 2633.5 | G8: 0 | H8: =F8-G8 -> 2633.5 | I8: =F8/G8-1 -> #DIV/0! | J8: =SUMIFS(CSM配件!AB:AB,CSM配件!R:R,$J$2,CSM配件!C:C,A8)+SUMIFS(WMS网点买断配件明细!I:I,WMS网点买断配件明细!K:K,$J$2,WMS网点买断配件明细!B:B,A8) -> 132 | K8: 936 | L8: =J8-K8 -> -804 | M8: =J8/K8-1 -> -0.85897436 | N8: =SUMIFS(CSM配件!AB:AB,CSM配件!R:R,$N$2,CSM配件!C:C,A8) -> 900 | O8: 5560 | P8: =N8-O8 -> -4660 | Q8: =N8/O8-1 -> -0.8381295
A9: 新疆办事处 | B9: =SUMIFS(CSM服务项目!Y:Y,CSM服务项目!Q:Q,$B$2,CSM服务项目!B:B,A9) -> 19558 | C9: 38500 | D9: =B9-C9 -> -18942 | E9: =B9/C9-1 -> -0.492 | F9: =SUMIFS(CSM服务项目!Y:Y,CSM服务项目!Q:Q,$F$2,CSM服务项目!B:B,A9) -> 7236.4 | G9: 1374 | H9: =F9-G9 -> 5862.4 | I9: =F9/G9-1 -> 4.2666667 | J9: =SUMIFS(CSM配件!AB:AB,CSM配件!R:R,$J$2,CSM配件!C:C,A9)+SUMIFS(WMS网点买断配件明细!I:I,WMS网点买断配件明细!K:K,$J$2,WMS网点买断配件明细!B:B,A9) -> 3875 | K9: 3619 | L9: =J9-K9 -> 256 | M9: =J9/K9-1 -> 0.070737773 | N9: =SUMIFS(CSM配件!AB:AB,CSM配件!R:R,$N$2,CSM配件!C:C,A9) -> 22500 | O9: 47280 | P9: =N9-O9 -> -24780 | Q9: =N9/O9-1 -> -0.52411168
A10: 小计 | B10: =SUM(B4:B9) -> 34804 | C10: =SUM(C4:C9) -> 75318 | D10: =B10-C10 -> -40514 | E10: =B10/C10-1 -> -0.53790595 | F10: =SUM(F4:F9) -> 22165.7 | G10: =SUM(G4:G9) -> 6565.4 | H10: =F10-G10 -> 15600.3 | I10: =F10/G10-1 -> 2.3761385 | J10: =SUM(J4:J9) -> 13740 | K10: =SUM(K4:K9) -> 19421 | L10: =J10-K10 -> -5681 | M10: =J10/K10-1 -> -0.29251841 | N10: =SUM(N4:N9) -> 53440 | O10: =SUM(O4:O9) -> 129940 | P10: =N10-O10 -> -76500 | Q10: =N10/O10-1 -> -0.58873326

Sheet 网点数据
A1: 西北大区服务网点收入统计
A2: 办事处 | B2: 服务网点 | C2: 清洗保养 | D2: 延保服务 | E2: 止回阀 | F2: 装饰罩 | G2: 清洁耗材 | H2: 水/气路金属软管 | I2: 其他产品线专用 | J2: 排烟出风管 | K2: 其他水路辅材 | L2: 其他气路辅材 | M2: 橱柜类辅材 | N2: 水气路通用辅材 | O2: 燃气管快速接头 | P2: 工具 | Q2: 合计 | R2: 三大爆品合计 | S2: 任务 | T2: 完成进度
A3: 包头办事处 | B3: 包头服务中心零售网点 | C3: =SUMIFS(CSM服务项目!Y:Y,CSM服务项目!Q:Q,$C$2,CSM服务项目!D:D,B3) -> 928 | D3: =SUMIFS(CSM服务项目!Y:Y,CSM服务项目!Q:Q,$D$2,CSM服务项目!D:D,B3) -> 0 | E3: =SUMIFS(CSM配件!AB:AB,CSM配件!R:R,$E$2,CSM配件!D:D,B3) -> 360 | F3: =SUMIFS(CSM配件!AB:AB,CSM配件!R:R,$F$2,CSM配件!D:D,B3) -> 0 | G3: =SUMIFS(CSM配件!AB:AB,CSM配件!R:R,$G$2,CSM配件!D:D,B3)+SUMIFS(WMS网点买断配件明细!I:I,WMS网点买断配件明细!K:K,$G$2,WMS网点买断配件明细!D:D,B3) -> 273 | H3: =SUMIFS(CSM配件!AB:AB,CSM配件!R:R,$H$2,CSM配件!D:D,B3)+SUMIFS(WMS网点买断配件明细!I:I,WMS网点买断配件明细!K:K,$H$2,WMS网点买断配件明细!D:D,B3) -> 0 | I3: =SUMIFS(CSM配件!AB:AB,CSM配件!R:R,$I$2,CSM配件!D:D,B3)+SUMIFS(WMS网点买断配件明细!I:I,WMS网点买断配件明细!K:K,$I$2,WMS网点买断配件明细!D:D,B3) -> 1120 | J3: =SUMIFS(CSM配件!AB:AB,CSM配件!R:R,$J$2,CSM配件!D:D,B3)+SUMIFS(WMS网点买断配件明细!I:I,WMS网点买断配件明细!K:K,$J$2,WMS网点买断配件明细!D:D,B3) -> 50 | K3: =SUMIFS(CSM配件!AB:AB,CSM配件!R:R,$K$2,CSM配件!D:D,B3)+SUMIFS(WMS网点买断配件明细!I:I,WMS网点买断配件明细!K:K,$K$2,WMS网点买断配件明细!D:D,B3) -> 0 | L3: =SUMIFS(CSM配件!AB:AB,CSM配件!R:R,$L$2,CSM配件!D:D,B3)+SUMIFS(WMS网点买断配件明细!I:I,WMS网点买断配件明细!K:K,$L$2,WMS网点买断配件明细!D:D,B3) -> 0 | M3: =SUMIFS(CSM配件!AB:AB,CSM配件!R:R,$M$2,CSM配件!D:D,B3)+SUMIFS(WMS网点买断配件明细!I:I,WMS网点买断配件明细!K:K,$M$2,WMS网点买断配件明细!D:D,B3) -> 50 | N3: =SUMIFS(CSM配件!AB:AB,CSM配件!R:R,$N$2,CSM配件!D:D,B3)+SUMIFS(WMS网点买断配件明细!I:I,WMS网点买断配件明细!K:K,$N$2,WMS网点买断配件明细!D:D,B3) -> 0 | O3: =SUMIFS(CSM配件!AB:AB,CSM配件!R:R,$O$2,CSM配件!D:D,B3)+SUMIFS(WMS网点买断配件明细!I:I,WMS网点买断配件明细!K:K,$O$2,WMS网点买断配件明细!D:D,B3) -> 0 | P3: =SUMIFS(CSM配件!AB:AB,CSM配件!R:R,$P$2,CSM配件!D:D,B3)+SUMIFS(WMS网点买断配件明细!I:I,WMS网点买断配件明细!K:K,$P$2,WMS网点买断配件明细!D:D,B3) -> 0 | Q3: =SUM(C3:P3) -> 2781 | R3: =C3+D3+G3 -> 1201
A4: 包头办事处 | B4: 东胜区赵全笑家电维修服务部 | C4: =SUMIFS(CSM服务项目!Y:Y,CSM服务项目!Q:Q,$C$2,CSM服务项目!D:D,B4) -> 0 | D4: =SUMIFS(CSM服务项目!Y:Y,CSM服务项目!Q:Q,$D$2,CSM服务项目!D:D,B4) -> 0 | E4: =SUMIFS(CSM配件!AB:AB,CSM配件!R:R,$E$2,CSM配件!D:D,B4) -> 1100 | F4: =SUMIFS(CSM配件!AB:AB,CSM配件!R:R,$F$2,CSM配件!D:D,B4) -> 0 | G4: =SUMIFS(CSM配件!AB:AB,CSM配件!R:R,$G$2,CSM配件!D:D,B4)+SUMIFS(WMS网点买断配件明细!I:I,WMS网点买断配件明细!K:K,$G$2,WMS网点买断配件明细!D:D,B4) -> 1220 | H4: =SUMIFS(CSM配件!AB:AB,CSM配件!R:R,$H$2,CSM配件!D:D,B4)+SUMIFS(WMS网点买断配件明细!I:I,WMS网点买断配件明细!K:K,$H$2,WMS网点买断配件明细!D:D,B4) -> 0 | I4: =SUMIFS(CSM配件!AB:AB,CSM配件!R:R,$I$2,CSM配件!D:D,B4)+SUMIFS(WMS网点买断配件明细!I:I,WMS网点买断配件明细!K:K,$I$2,WMS网点买断配件明细!D:D,B4) -> 840 | J4: =SUMIFS(CSM配件!AB:AB,CSM配件!R:R,$J$2,CSM配件!D:D,B4)+SUMIFS(WMS网点买断配件明细!I:I,WMS网点买断配件明细!K:K,$J$2,WMS网点买断配件明细!D:D,B4) -> 52.5 | K4: =SUMIFS(CSM配件!AB:AB,CSM配件!R:R,$K$2,CSM配件!D:D,B4)+SUMIFS(WMS网点买断配件明细!I:I,WMS网点买断配件明细!K:K,$K$2,WMS网点买断配件明细!D:D,B4) -> 196 | L4: =SUMIFS(CSM配件!AB:AB,CSM配件!R:R,$L$2,CSM配件!D:D,B4)+SUMIFS(WMS网点买断配件明细!I:I,WMS网点买断配件明细!K:K,$L$2,WMS网点买断配件明细!D:D,B4) -> 0 | M4: =SUMIFS(CSM配件!AB:AB,CSM配件!R:R,$M$2,CSM配件!D:D,B4)+SUMIFS(WMS网点买断配件明细!I:I,WMS网点买断配件明细!K:K,$M$2,WMS网点买断配件明细!D:D,B4) -> 17.5 | N4: =SUMIFS(CSM配件!AB:AB,CSM配件!R:R,$N$2,CSM配件!D:D,B4)+SUMIFS(WMS网点买断配件明细!I:I,WMS网点买断配件明细!K:K,$N$2,WMS网点买断配件明细!D:D,B4) -> 0 | O4: =SUMIFS(CSM配件!AB:AB,CSM配件!R:R,$O$2,CSM配件!D:D,B4)+SUMIFS(WMS网点买断配件明细!I:I,WMS网点买断配件明细!K:K,$O$2,WMS网点买断配件明细!D:D,B4) -> 0 | P4: =SUMIFS(CSM配件!AB:AB,CSM配件!R:R,$P$2,CSM配件!D:D,B4)+SUMIFS(WMS网点买断配件明细!I:I,WMS网点买断配件明细!K:K,$P$2,WMS网点买断配件明细!D:D,B4) -> 0 | Q4: =SUM(C4:P4) -> 3426 | R4: =C4+D4+G4 -> 1220
A5: 包头办事处 | B5: 海勃湾区福心圆家电维修服务部（个体工商户） | C5: =SUMIFS(CSM服务项目!Y:Y,CSM服务项目!Q:Q,$C$2,CSM服务项目!D:D,B5) -> 0 | D5: =SUMIFS(CSM服务项目!Y:Y,CSM服务项目!Q:Q,$D$2,CSM服务项目!D:D,B5) -> 0 | E5: =SUMIFS(CSM配件!AB:AB,CSM配件!R:R,$E$2,CSM配件!D:D,B5) -> 500 | F5: =SUMIFS(CSM配件!AB:AB,CSM配件!R:R,$F$2,CSM配件!D:D,B5) -> 0 | G5: =SUMIFS(CSM配件!AB:AB,CSM配件!R:R,$G$2,CSM配件!D:D,B5)+SUMIFS(WMS网点买断配件明细!I:I,WMS网点买断配件明细!K:K,$G$2,WMS网点买断配件明细!D:D,B5) -> 95 | H5: =SUMIFS(CSM配件!AB:AB,CSM配件!R:R,$H$2,CSM配件!D:D,B5)+SUMIFS(WMS网点买断配件明细!I:I,WMS网点买断配件明细!K:K,$H$2,WMS网点买断配件明细!D:D,B5) -> 0 | I5: =SUMIFS(CSM配件!AB:AB,CSM配件!R:R,$I$2,CSM配件!D:D,B5)+SUMIFS(WMS网点买断配件明细!I:I,WMS网点买断配件明细!K:K,$I$2,WMS网点买断配件明细!D:D,B5) -> 322 | J5: =SUMIFS(CSM配件!AB:AB,CSM配件!R:R,$J$2,CSM配件!D:D,B5)+SUMIFS(WMS网点买断配件明细!I:I,WMS网点买断配件明细!K:K,$J$2,WMS网点买断配件明细!D:D,B5) -> 0 | K5: =SUMIFS(CSM配件!AB:AB,CSM配件!R:R,$K$2,CSM配件!D:D,B5)+SUMIFS(WMS网点买断配件明细!I:I,WMS网点买断配件明细!K:K,$K$2,WMS网点买断配件明细!D:D,B5) -> 0 | L5: =SUMIFS(CSM配件!AB:AB,CSM配件!R:R,$L$2,CSM配件!D:D,B5)+SUMIFS(WMS网点买断配件明细!I:I,WMS网点买断配件明细!K:K,$L$2,WMS网点买断配件明细!D:D,B5) -> 0 | M5: =SUMIFS(CSM配件!AB:AB,CSM配件!R:R,$M$2,CSM配件!D:D,B5)+SUMIFS(WMS网点买断配件明细!I:I,WMS网点买断配件明细!K:K,$M$2,WMS网点买断配件明细!D:D,B5) -> 0 | N5: =SUMIFS(CSM配件!AB:AB,CSM配件!R:R,$N$2,CSM配件!D:D,B5)+SUMIFS(WMS网点买断配件明细!I:I,WMS网点买断配件明细!K:K,$N$2,WMS网点买断配件明细!D:D,B5) -> 0 | O5: =SUMIFS(CSM配件!AB:AB,CSM配件!R:R,$O$2,CSM配件!D:D,B5)+SUMIFS(WMS网点买断配件明细!I:I,WMS网点买断配件明细!K:K,$O$2,WMS网点买断配件明细!D:D,B5) -> 0 | P5: =SUMIFS(CSM配件!AB:AB,CSM配件!R:R,$P$2,CSM配件!D:D,B5)+SUMIFS(WMS网点买断配件明细!I:I,WMS网点买断配件明细!K:K,$P$2,WMS网点买断配件明细!D:D,B5) -> 0 | Q5: =SUM(C5:P5) -> 917 | R5: =C5+D5+G5 -> 95
A6: 包头办事处 | B6: 杭锦后旗李杰家电卫浴维修服务中心 | C6: =SUMIFS(CSM服务项目!Y:Y,CSM服务项目!Q:Q,$C$2,CSM服务项目!D:D,B6) -> 0 | D6: =SUMIFS(CSM服务项目!Y:Y,CSM服务项目!Q:Q,$D$2,CSM服务项目!D:D,B6) -> 0 | E6: =SUMIFS(CSM配件!AB:AB,CSM配件!R:R,$E$2,CSM配件!D:D,B6) -> 0 | F6: =SUMIFS(CSM配件!AB:AB,CSM配件!R:R,$F$2,CSM配件!D:D,B6) -> 0 | G6: =SUMIFS(CSM配件!AB:AB,CSM配件!R:R,$G$2,CSM配件!D:D,B6)+SUMIFS(WMS网点买断配件明细!I:I,WMS网点买断配件明细!K:K,$G$2,WMS网点买断配件明细!D:D,B6) -> 0 | H6: =SUMIFS(CSM配件!AB:AB,CSM配件!R:R,$H$2,CSM配件!D:D,B6)+SUMIFS(WMS网点买断配件明细!I:I,WMS网点买断配件明细!K:K,$H$2,WMS网点买断配件明细!D:D,B6) -> 0 | I6: =SUMIFS(CSM配件!AB:AB,CSM配件!R:R,$I$2,CSM配件!D:D,B6)+SUMIFS(WMS网点买断配件明细!I:I,WMS网点买断配件明细!K:K,$I$2,WMS网点买断配件明细!D:D,B6) -> 70 | J6: =SUMIFS(CSM配件!AB:AB,CSM配件!R:R,$J$2,CSM配件!D:D,B6)+SUMIFS(WMS网点买断配件明细!I:I,WMS网点买断配件明细!K:K,$J$2,WMS网点买断配件明细!D:D,B6) -> 0 | K6: =SUMIFS(CSM配件!AB:AB,CSM配件!R:R,$K$2,CSM配件!D:D,B6)+SUMIFS(WMS网点买断配件明细!I:I,WMS网点买断配件明细!K:K,$K$2,WMS网点买断配件明细!D:D,B6) -> 0 | L6: =SUMIFS(CSM配件!AB:AB,CSM配件!R:R,$L$2,CSM配件!D:D,B6)+SUMIFS(WMS网点买断配件明细!I:I,WMS网点买断配件明细!K:K,$L$2,WMS网点买断配件明细!D:D,B6) -> 0 | M6: =SUMIFS(CSM配件!AB:AB,CSM配件!R:R,$M$2,CSM配件!D:D,B6)+SUMIFS(WMS网点买断配件明细!I:I,WMS网点买断配件明细!K:K,$M$2,WMS网点买断配件明细!D:D,B6) -> 0 | N6: =SUMIFS(CSM配件!AB:AB,CSM配件!R:R,$N$2,CSM配件!D:D,B6)+SUMIFS(WMS网点买断配件明细!I:I,WMS网点买断配件明细!K:K,$N$2,WMS网点买断配件明细!D:D,B6) -> 0 | O6: =SUMIFS(CSM配件!AB:AB,CSM配件!R:R,$O$2,CSM配件!D:D,B6)+SUMIFS(WMS网点买断配件明细!I:I,WMS网点买断配件明细!K:K,$O$2,WMS网点买断配件明细!D:D,B6) -> 0 | P6: =SUMIFS(CSM配件!AB:AB,CSM配件!R:R,$P$2,CSM配件!D:D,B6)+SUMIFS(WMS网点买断配件明细!I:I,WMS网点买断配件明细!K:K,$P$2,WMS网点买断配件明细!D:D,B6) -> 0 | Q6: =SUM(C6:P6) -> 70 | R6: =C6+D6+G6 -> 0
A7: 包头办事处 | B7: 康巴什区中福家电维修服务部 | C7: =SUMIFS(CSM服务项目!Y:Y,CSM服务项目!Q:Q,$C$2,CSM服务项目!D:D,B7) -> 0 | D7: =SUMIFS(CSM服务项目!Y:Y,CSM服务项目!Q:Q,$D$2,CSM服务项目!D:D,B7) -> 0 | E7: =SUMIFS(CSM配件!AB:AB,CSM配件!R:R,$E$2,CSM配件!D:D,B7) -> 1100 | F7: =SUMIFS(CSM配件!AB:AB,CSM配件!R:R,$F$2,CSM配件!D:D,B7) -> 0 | G7: =SUMIFS(CSM配件!AB:AB,CSM配件!R:R,$G$2,CSM配件!D:D,B7)+SUMIFS(WMS网点买断配件明细!I:I,WMS网点买断配件明细!K:K,$G$2,WMS网点买断配件明细!D:D,B7) -> 228 | H7: =SUMIFS(CSM配件!AB:AB,CSM配件!R:R,$H$2,CSM配件!D:D,B7)+SUMIFS(WMS网点买断配件明细!I:I,WMS网点买断配件明细!K:K,$H$2,WMS网点买断配件明细!D:D,B7) -> 0 | I7: =SUMIFS(CSM配件!AB:AB,CSM配件!R:R,$I$2,CSM配件!D:D,B7)+SUMIFS(WMS网点买断配件明细!I:I,WMS网点买断配件明细!K:K,$I$2,WMS网点买断配件明细!D:D,B7) -> 567 | J7: =SUMIFS(CSM配件!AB:AB,CSM配件!R:R,$J$2,CSM配件!D:D,B7)+SUMIFS(WMS网点买断配件明细!I:I,WMS网点买断配件明细!K:K,$J$2,WMS网点买断配件明细!D:D,B7) -> 105 | K7: =SUMIFS(CSM配件!AB:AB,CSM配件!R:R,$K$2,CSM配件!D:D,B7)+SUMIFS(WMS网点买断配件明细!I:I,WMS网点买断配件明细!K:K,$K$2,WMS网点买断配件明细!D:D,B7) -> 0 | L7: =SUMIFS(CSM配件!AB:AB,CSM配件!R:R,$L$2,CSM配件!D:D,B7)+SUMIFS(WMS网点买断配件明细!I:I,WMS网点买断配件明细!K:K,$L$2,WMS网点买断配件明细!D:D,B7) -> 0 | M7: =SUMIFS(CSM配件!AB:AB,CSM配件!R:R,$M$2,CSM配件!D:D,B7)+SUMIFS(WMS网点买断配件明细!I:I,WMS网点买断配件明细!K:K,$M$2,WMS网点买断配件明细!D:D,B7) -> 0 | N7: =SUMIFS(CSM配件!AB:AB,CSM配件!R:R,$N$2,CSM配件!D:D,B7)+SUMIFS(WMS网点买断配件明细!I:I,WMS网点买断配件明细!K:K,$N$2,WMS网点买断配件明细!D:D,B7) -> 0 | O7: =SUMIFS(CSM配件!AB:AB,CSM配件!R:R,$O$2,CSM配件!D:D,B7)+SUMIFS(WMS网点买断配件明细!I:I,WMS网点买断配件明细!K:K,$O$2,WMS网点买断配件明细!D:D,B7) -> 0 | P7: =SUMIFS(CSM配件!AB:AB,CSM配件!R:R,$P$2,CSM配件!D:D,B7)+SUMIFS(WMS网点买断配件明细!I:I,WMS网点买断配件明细!K:K,$P$2,WMS网点买断配件明细!D:D,B7) -> 0 | Q7: =SUM(C7:P7) -> 2000 | R7: =C7+D7+G7 -> 228
A8: 包头办事处 | B8: 昆都仑区王宏明家电安装部 | C8: =SUMIFS(CSM服务项目!Y:Y,CSM服务项目!Q:Q,$C$2,CSM服务项目!D:D,B8) -> 0 | D8: =SUMIFS(CSM服务项目!Y:Y,CSM服务项目!Q:Q,$D$2,CSM服务项目!D:D,B8) -> 0 | E8: =SUMIFS(CSM配件!AB:AB,CSM配件!R:R,$E$2,CSM配件!D:D,B8) -> 100 | F8: =SUMIFS(CSM配件!AB:AB,CSM配件!R:R,$F$2,CSM配件!D:D,B8) -> 0 | G8: =SUMIFS(CSM配件!AB:AB,CSM配件!R:R,$G$2,CSM配件!D:D,B8)+SUMIFS(WMS网点买断配件明细!I:I,WMS网点买断配件明细!K:K,$G$2,WMS网点买断配件明细!D:D,B8) -> 40 | H8: =SUMIFS(CSM配件!AB:AB,CSM配件!R:R,$H$2,CSM配件!D:D,B8)+SUMIFS(WMS网点买断配件明细!I:I,WMS网点买断配件明细!K:K,$H$2,WMS网点买断配件明细!D:D,B8) -> 0 | I8: =SUMIFS(CSM配件!AB:AB,CSM配件!R:R,$I$2,CSM配件!D:D,B8)+SUMIFS(WMS网点买断配件明细!I:I,WMS网点买断配件明细!K:K,$I$2,WMS网点买断配件明细!D:D,B8) -> 280 | J8: =SUMIFS(CSM配件!AB:AB,CSM配件!R:R,$J$2,CSM配件!D:D,B8)+SUMIFS(WMS网点买断配件明细!I:I,WMS网点买断配件明细!K:K,$J$2,WMS网点买断配件明细!D:D,B8) -> 0 | K8: =SUMIFS(CSM配件!AB:AB,CSM配件!R:R,$K$2,CSM配件!D:D,B8)+SUMIFS(WMS网点买断配件明细!I:I,WMS网点买断配件明细!K:K,$K$2,WMS网点买断配件明细!D:D,B8) -> 0 | L8: =SUMIFS(CSM配件!AB:AB,CSM配件!R:R,$L$2,CSM配件!D:D,B8)+SUMIFS(WMS网点买断配件明细!I:I,WMS网点买断配件明细!K:K,$L$2,WMS网点买断配件明细!D:D,B8) -> 0 | M8: =SUMIFS(CSM配件!AB:AB,CSM配件!R:R,$M$2,CSM配件!D:D,B8)+SUMIFS(WMS网点买断配件明细!I:I,WMS网点买断配件明细!K:K,$M$2,WMS网点买断配件明细!D:D,B8) -> 52.5 | N8: =SUMIFS(CSM配件!AB:AB,CSM配件!R:R,$N$2,CSM配件!D:D,B8)+SUMIFS(WMS网点买断配件明细!I:I,WMS网点买断配件明细!K:K,$N$2,WMS网点买断配件明细!D:D,B8) -> 0 | O8: =SUMIFS(CSM配件!AB:AB,CSM配件!R:R,$O$2,CSM配件!D:D,B8)+SUMIFS(WMS网点买断配件明细!I:I,WMS网点买断配件明细!K:K,$O$2,WMS网点买断配件明细!D:D,B8) -> 0 | P8: =SUMIFS(CSM配件!AB:AB,CSM配件!R:R,$P$2,CSM配件!D:D,B8)+SUMIFS(WMS网点买断配件明细!I:I,WMS网点买断配件明细!K:K,$P$2,WMS网点买断配件明细!D:D,B8) -> 0 | Q8: =SUM(C8:P8) -> 472.5 | R8: =C8+D8+G8 -> 40
A9: 包头办事处 | B9: 临河区范慧明家电维修中心 | C9: =SUMIFS(CSM服务项目!Y:Y,CSM服务项目!Q:Q,$C$2,CSM服务项目!D:D,B9) -> 75 | D9: =SUMIFS(CSM服务项目!Y:Y,CSM服务项目!Q:Q,$D$2,CSM服务项目!D:D,B9) -> 0 | E9: =SUMIFS(CSM配件!AB:AB,CSM配件!R:R,$E$2,CSM配件!D:D,B9) -> 300 | F9: =SUMIFS(CSM配件!AB:AB,CSM配件!R:R,$F$2,CSM配件!D:D,B9) -> 0 | G9: =SUMIFS(CSM配件!AB:AB,CSM配件!R:R,$G$2,CSM配件!D:D,B9)+SUMIFS(WMS网点买断配件明细!I:I,WMS网点买断配件明细!K:K,$G$2,WMS网点买断配件明细!D:D,B9) -> 0 | H9: =SUMIFS(CSM配件!AB:AB,CSM配件!R:R,$H$2,CSM配件!D:D,B9)+SUMIFS(WMS网点买断配件明细!I:I,WMS网点买断配件明细!K:K,$H$2,WMS网点买断配件明细!D:D,B9) -> 0 | I9: =SUMIFS(CSM配件!AB:AB,CSM配件!R:R,$I$2,CSM配件!D:D,B9)+SUMIFS(WMS网点买断配件明细!I:I,WMS网点买断配件明细!K:K,$I$2,WMS网点买断配件明细!D:D,B9) -> 210 | J9: =SUMIFS(CSM配件!AB:AB,CSM配件!R:R,$J$2,CSM配件!D:D,B9)+SUMIFS(WMS网点买断配件明细!I:I,WMS网点买断配件明细!K:K,$J$2,WMS网点买断配件明细!D:D,B9) -> 129.5 | K9: =SUMIFS(CSM配件!AB:AB,CSM配件!R:R,$K$2,CSM配件!D:D,B9)+SUMIFS(WMS网点买断配件明细!I:I,WMS网点买断配件明细!K:K,$K$2,WMS网点买断配件明细!D:D,B9) -> 0 | L9: =SUMIFS(CSM配件!AB:AB,CSM配件!R:R,$L$2,CSM配件!D:D,B9)+SUMIFS(WMS网点买断配件明细!I:I,WMS网点买断配件明细!K:K,$L$2,WMS网点买断配件明细!D:D,B9) -> 0 | M9: =SUMIFS(CSM配件!AB:AB,CSM配件!R:R,$M$2,CSM配件!D:D,B9)+SUMIFS(WMS网点买断配件明细!I:I,WMS网点买断配件明细!K:K,$M$2,WMS网点买断配件明细!D:D,B9) -> 0 | N9: =SUMIFS(CSM配件!AB:AB,CSM配件!R:R,$N$2,CSM配件!D:D,B9)+SUMIFS(WMS网点买断配件明细!I:I,WMS网点买断配件明细!K:K,$N$2,WMS网点买断配件明细!D:D,B9) -> 0 | O9: =SUMIFS(CSM配件!AB:AB,CSM配件!R:R,$O$2,CSM配件!D:D,B9)+SUMIFS(WMS网点买断配件明细!I:I,WMS网点买断配件明细!K:K,$O$2,WMS网点买断配件明细!D:D,B9) -> 0 | P9: =SUMIFS(CSM配件!AB:AB,CSM配件!R:R,$P$2,CSM配件!D:D,B9)+SUMIFS(WMS网点买断配件明细!I:I,WMS网点买断配件明细!K:K,$P$2,WMS网点买断配件明细!D:D,B9) -> 0 | Q9: =SUM(C9:P9) -> 714.5 | R9: =C9+D9+G9 -> 75
A10: 包头办事处 | B10: 青山区厨小帮家电维修门店 | C10: =SUMIFS(CSM服务项目!Y:Y,CSM服务项目!Q:Q,$C$2,CSM服务项目!D:D,B10) -> 450 | D10: =SUMIFS(CSM服务项目!Y:Y,CSM服务项目!Q:Q,$D$2,CSM服务项目!D:D,B10) -> 343.5 | E10: =SUMIFS(CSM配件!AB:AB,CSM配件!R:R,$E$2,CSM配件!D:D,B10) -> 200 | F10: =SUMIFS(CSM配件!AB:AB,CSM配件!R:R,$F$2,CSM配件!D:D,B10) -> 0 | G10: =SUMIFS(CSM配件!AB:AB,CSM配件!R:R,$G$2,CSM配件!D:D,B10)+SUMIFS(WMS网点买断配件明细!I:I,WMS网点买断配件明细!K:K,$G$2,WMS网点买断配件明细!D:D,B10) -> 520 | H10: =SUMIFS(CSM配件!AB:AB,CSM配件!R:R,$H$2,CSM配件!D:D,B10)+SUMIFS(WMS网点买断配件明细!I:I,WMS网点买断配件明细!K:K,$H$2,WMS网点买断配件明细!D:D,B10) -> 408.21 | I10: =SUMIFS(CSM配件!AB:AB,CSM配件!R:R,$I$2,CSM配件!D:D,B10)+SUMIFS(WMS网点买断配件明细!I:I,WMS网点买断配件明细!K:K,$I$2,WMS网点买断配件明细!D:D,B10) -> 560 | J10: =SUMIFS(CSM配件!AB:AB,CSM配件!R:R,$J$2,CSM配件!D:D,B10)+SUMIFS(WMS网点买断配件明细!I:I,WMS网点买断配件明细!K:K,$J$2,WMS网点买断配件明细!D:D,B10) -> 0 | K10: =SUMIFS(CSM配件!AB:AB,CSM配件!R:R,$K$2,CSM配件!D:D,B10)+SUMIFS(WMS网点买断配件明细!I:I,WMS网点买断配件明细!K:K,$K$2,WMS网点买断配件明细!D:D,B10) -> 0 | L10: =SUMIFS(CSM配件!AB:AB,CSM配件!R:R,$L$2,CSM配件!D:D,B10)+SUMIFS(WMS网点买断配件明细!I:I,WMS网点买断配件明细!K:K,$L$2,WMS网点买断配件明细!D:D,B10) -> 0 | M10: =SUMIFS(CSM配件!AB:AB,CSM配件!R:R,$M$2,CSM配件!D:D,B10)+SUMIFS(WMS网点买断配件明细!I:I,WMS网点买断配件明细!K:K,$M$2,WMS网点买断配件明细!D:D,B10) -> 35 | N10: =SUMIFS(CSM配件!AB:AB,CSM配件!R:R,$N$2,CSM配件!D:D,B10)+SUMIFS(WMS网点买断配件明细!I:I,WMS网点买断配件明细!K:K,$N$2,WMS网点买断配件明细!D:D,B10) -> 0 | O10: =SUMIFS(CSM配件!AB:AB,CSM配件!R:R,$O$2,CSM配件!D:D,B10)+SUMIFS(WMS网点买断配件明细!I:I,WMS网点买断配件明细!K:K,$O$2,WMS网点买断配件明细!D:D,B10) -> 44.4 | P10: =SUMIFS(CSM配件!AB:AB,CSM配件!R:R,$P$2,CSM配件!D:D,B10)+SUMIFS(WMS网点买断配件明细!I:I,WMS网点买断配件明细!K:K,$P$2,WMS网点买断配件明细!D:D,B10) -> 0 | Q10: =SUM(C10:P10) -> 2561.11 | R10: =C10+D10+G10 -> 1313.5
A11: 包头办事处 | B11: 乌拉特前旗乌拉山方容厨房电器 | C11: =SUMIFS(CSM服务项目!Y:Y,CSM服务项目!Q:Q,$C$2,CSM服务项目!D:D,B11) -> 0 | D11: =SUMIFS(CSM服务项目!Y:Y,CSM服务项目!Q:Q,$D$2,CSM服务项目!D:D,B11) -> 0 | E11: =SUMIFS(CSM配件!AB:AB,CSM配件!R:R,$E$2,CSM配件!D:D,B11) -> 0 | F11: =SUMIFS(CSM配件!AB:AB,CSM配件!R:R,$F$2,CSM配件!D:D,B11) -> 0 | G11: =SUMIFS(CSM配件!AB:AB,CSM配件!R:R,$G$2,CSM配件!D:D,B11)+SUMIFS(WMS网点买断配件明细!I:I,WMS网点买断配件明细!K:K,$G$2,WMS网点买断配件明细!D:D,B11) -> 152 | H11: =SUMIFS(CSM配件!AB:AB,CSM配件!R:R,$H$2,CSM配件!D:D,B11)+SUMIFS(WMS网点买断配件明细!I:I,WMS网点买断配件明细!K:K,$H$2,WMS网点买断配件明细!D:D,B11) -> 0 | I11: =SUMIFS(CSM配件!AB:AB,CSM配件!R:R,$I$2,CSM配件!D:D,B11)+SUMIFS(WMS网点买断配件明细!I:I,WMS网点买断配件明细!K:K,$I$2,WMS网点买断配件明细!D:D,B11) -> 0 | J11: =SUMIFS(CSM配件!AB:AB,CSM配件!R:R,$J$2,CSM配件!D:D,B11)+SUMIFS(WMS网点买断配件明细!I:I,WMS网点买断配件明细!K:K,$J$2,WMS网点买断配件明细!D:D,B11) -> 0 | K11: =SUMIFS(CSM配件!AB:AB,CSM配件!R:R,$K$2,CSM配件!D:D,B11)+SUMIFS(WMS网点买断配件明细!I:I,WMS网点买断配件明细!K:K,$K$2,WMS网点买断配件明细!D:D,B11) -> 0 | L11: =SUMIFS(CSM配件!AB:AB,CSM配件!R:R,$L$2,CSM配件!D:D,B11)+SUMIFS(WMS网点买断配件明细!I:I,WMS网点买断配件明细!K:K,$L$2,WMS网点买断配件明细!D:D,B11) -> 0 | M11: =SUMIFS(CSM配件!AB:AB,CSM配件!R:R,$M$2,CSM配件!D:D,B11)+SUMIFS(WMS网点买断配件明细!I:I,WMS网点买断配件明细!K:K,$M$2,WMS网点买断配件明细!D:D,B11) -> 0 | N11: =SUMIFS(CSM配件!AB:AB,CSM配件!R:R,$N$2,CSM配件!D:D,B11)+SUMIFS(WMS网点买断配件明细!I:I,WMS网点买断配件明细!K:K,$N$2,WMS网点买断配件明细!D:D,B11) -> 0 | O11: =SUMIFS(CSM配件!AB:AB,CSM配件!R:R,$O$2,CSM配件!D:D,B11)+SUMIFS(WMS网点买断配件明细!I:I,WMS网点买断配件明细!K:K,$O$2,WMS网点买断配件明细!D:D,B11) -> 0 | P11: =SUMIFS(CSM配件!AB:AB,CSM配件!R:R,$P$2,CSM配件!D:D,B11)+SUMIFS(WMS网点买断配件明细!I:I,WMS网点买断配件明细!K:K,$P$2,WMS网点买断配件明细!D:D,B11) -> 0 | Q11: =SUM(C11:P11) -> 152 | R11: =C11+D11+G11 -> 152
A12: 包头办事处 | B12: 五原县万佳电器服务中心 | C12: =SUMIFS(CSM服务项目!Y:Y,CSM服务项目!Q:Q,$C$2,CSM服务项目!D:D,B12) -> 0 | D12: =SUMIFS(CSM服务项目!Y:Y,CSM服务项目!Q:Q,$D$2,CSM服务项目!D:D,B12) -> 0 | E12: =SUMIFS(CSM配件!AB:AB,CSM配件!R:R,$E$2,CSM配件!D:D,B12) -> 0 | F12: =SUMIFS(CSM配件!AB:AB,CSM配件!R:R,$F$2,CSM配件!D:D,B12) -> 0 | G12: =SUMIFS(CSM配件!AB:AB,CSM配件!R:R,$G$2,CSM配件!D:D,B12)+SUMIFS(WMS网点买断配件明细!I:I,WMS网点买断配件明细!K:K,$G$2,WMS网点买断配件明细!D:D,B12) -> 0 | H12: =SUMIFS(CSM配件!AB:AB,CSM配件!R:R,$H$2,CSM配件!D:D,B12)+SUMIFS(WMS网点买断配件明细!I:I,WMS网点买断配件明细!K:K,$H$2,WMS网点买断配件明细!D:D,B12) -> 0 | I12: =SUMIFS(CSM配件!AB:AB,CSM配件!R:R,$I$2,CSM配件!D:D,B12)+SUMIFS(WMS网点买断配件明细!I:I,WMS网点买断配件明细!K:K,$I$2,WMS网点买断配件明细!D:D,B12) -> 0 | J12: =SUMIFS(CSM配件!AB:AB,CSM配件!R:R,$J$2,CSM配件!D:D,B12)+SUMIFS(WMS网点买断配件明细!I:I,WMS网点买断配件明细!K:K,$J$2,WMS网点买断配件明细!D:D,B12) -> 0 | K12: =SUMIFS(CSM配件!AB:AB,CSM配件!R:R,$K$2,CSM配件!D:D,B12)+SUMIFS(WMS网点买断配件明细!I:I,WMS网点买断配件明细!K:K,$K$2,WMS网点买断配件明细!D:D,B12) -> 0 | L12: =SUMIFS(CSM配件!AB:AB,CSM配件!R:R,$L$2,CSM配件!D:D,B12)+SUMIFS(WMS网点买断配件明细!I:I,WMS网点买断配件明细!K:K,$L$2,WMS网点买断配件明细!D:D,B12) -> 0 | M12: =SUMIFS(CSM配件!AB:AB,CSM配件!R:R,$M$2,CSM配件!D:D,B12)+SUMIFS(WMS网点买断配件明细!I:I,WMS网点买断配件明细!K:K,$M$2,WMS网点买断配件明细!D:D,B12) -> 0 | N12: =SUMIFS(CSM配件!AB:AB,CSM配件!R:R,$N$2,CSM配件!D:D,B12)+SUMIFS(WMS网点买断配件明细!I:I,WMS网点买断配件明细!K:K,$N$2,WMS网点买断配件明细!D:D,B12) -> 0 | O12: =SUMIFS(CSM配件!AB:AB,CSM配件!R:R,$O$2,CSM配件!D:D,B12)+SUMIFS(WMS网点买断配件明细!I:I,WMS网点买断配件明细!K:K,$O$2,WMS网点买断配件明细!D:D,B12) -> 0 | P12: =SUMIFS(CSM配件!AB:AB,CSM配件!R:R,$P$2,CSM配件!D:D,B12)+SUMIFS(WMS网点买断配件明细!I:I,WMS网点买断配件明细!K:K,$P$2,WMS网点买断配件明细!D:D,B12) -> 0 | Q12: =SUM(C12:P12) -> 0 | R12: =C12+D12+G12 -> 0
A13: 包头办事处 | B13: 伊金霍洛旗刘庆春电器店 | C13: =SUMIFS(CSM服务项目!Y:Y,CSM服务项目!Q:Q,$C$2,CSM服务项目!D:D,B13) -> 0 | D13: =SUMIFS(CSM服务项目!Y:Y,CSM服务项目!Q:Q,$D$2,CSM服务项目!D:D,B13) -> 0 | E13: =SUMIFS(CSM配件!AB:AB,CSM配件!R:R,$E$2,CSM配件!D:D,B13) -> 100 | F13: =SUMIFS(CSM配件!AB:AB,CSM配件!R:R,$F$2,CSM配件!D:D,B13) -> 0 | G13: =SUMIFS(CSM配件!AB:AB,CSM配件!R:R,$G$2,CSM配件!D:D,B13)+SUMIFS(WMS网点买断配件明细!I:I,WMS网点买断配件明细!K:K,$G$2,WMS网点买断配件明细!D:D,B13) -> 0 | H13: =SUMIFS(CSM配件!AB:AB,CSM配件!R:R,$H$2,CSM配件!D:D,B13)+SUMIFS(WMS网点买断配件明细!I:I,WMS网点买断配件明细!K:K,$H$2,WMS网点买断配件明细!D:D,B13) -> 0 | I13: =SUMIFS(CSM配件!AB:AB,CSM配件!R:R,$I$2,CSM配件!D:D,B13)+SUMIFS(WMS网点买断配件明细!I:I,WMS网点买断配件明细!K:K,$I$2,WMS网点买断配件明细!D:D,B13) -> 280 | J13: =SUMIFS(CSM配件!AB:AB,CSM配件!R:R,$J$2,CSM配件!D:D,B13)+SUMIFS(WMS网点买断配件明细!I:I,WMS网点买断配件明细!K:K,$J$2,WMS网点买断配件明细!D:D,B13) -> 35 | K13: =SUMIFS(CSM配件!AB:AB,CSM配件!R:R,$K$2,CSM配件!D:D,B13)+SUMIFS(WMS网点买断配件明细!I:I,WMS网点买断配件明细!K:K,$K$2,WMS网点买断配件明细!D:D,B13) -> 0 | L13: =SUMIFS(CSM配件!AB:AB,CSM配件!R:R,$L$2,CSM配件!D:D,B13)+SUMIFS(WMS网点买断配件明细!I:I,WMS网点买断配件明细!K:K,$L$2,WMS网点买断配件明细!D:D,B13) -> 0 | M13: =SUMIFS(CSM配件!AB:AB,CSM配件!R:R,$M$2,CSM配件!D:D,B13)+SUMIFS(WMS网点买断配件明细!I:I,WMS网点买断配件明细!K:K,$M$2,WMS网点买断配件明细!D:D,B13) -> 0 | N13: =SUMIFS(CSM配件!AB:AB,CSM配件!R:R,$N$2,CSM配件!D:D,B13)+SUMIFS(WMS网点买断配件明细!I:I,WMS网点买断配件明细!K:K,$N$2,WMS网点买断配件明细!D:D,B13) -> 0 | O13: =SUMIFS(CSM配件!AB:AB,CSM配件!R:R,$O$2,CSM配件!D:D,B13)+SUMIFS(WMS网点买断配件明细!I:I,WMS网点买断配件明细!K:K,$O$2,WMS网点买断配件明细!D:D,B13) -> 0 | P13: =SUMIFS(CSM配件!AB:AB,CSM配件!R:R,$P$2,CSM配件!D:D,B13)+SUMIFS(WMS网点买断配件明细!I:I,WMS网点买断配件明细!K:K,$P$2,WMS网点买断配件明细!D:D,B13) -> 0 | Q13: =SUM(C13:P13) -> 415 | R13: =C13+D13+G13 -> 0
A14: 呼和浩特办事处 | B14: 呼和浩特服务中心零售网点 | C14: =SUMIFS(CSM服务项目!Y:Y,CSM服务项目!Q:Q,$C$2,CSM服务项目!D:D,B14) -> 0 | D14: =SUMIFS(CSM服务项目!Y:Y,CSM服务项目!Q:Q,$D$2,CSM服务项目!D:D,B14) -> 0 | E14: =SUMIFS(CSM配件!AB:AB,CSM配件!R:R,$E$2,CSM配件!D:D,B14) -> 180 | F14: =SUMIFS(CSM配件!AB:AB,CSM配件!R:R,$F$2,CSM配件!D:D,B14) -> 0 | G14: =SUMIFS(CSM配件!AB:AB,CSM配件!R:R,$G$2,CSM配件!D:D,B14)+SUMIFS(WMS网点买断配件明细!I:I,WMS网点买断配件明细!K:K,$G$2,WMS网点买断配件明细!D:D,B14) -> 221 | H14: =SUMIFS(CSM配件!AB:AB,CSM配件!R:R,$H$2,CSM配件!D:D,B14)+SUMIFS(WMS网点买断配件明细!I:I,WMS网点买断配件明细!K:K,$H$2,WMS网点买断配件明细!D:D,B14) -> 150 | I14: =SUMIFS(CSM配件!AB:AB,CSM配件!R:R,$I$2,CSM配件!D:D,B14)+SUMIFS(WMS网点买断配件明细!I:I,WMS网点买断配件明细!K:K,$I$2,WMS网点买断配件明细!D:D,B14) -> 705 | J14: =SUMIFS(CSM配件!AB:AB,CSM配件!R:R,$J$2,CSM配件!D:D,B14)+SUMIFS(WMS网点买断配件明细!I:I,WMS网点买断配件明细!K:K,$J$2,WMS网点买断配件明细!D:D,B14) -> 220 | K14: =SUMIFS(CSM配件!AB:AB,CSM配件!R:R,$K$2,CSM配件!D:D,B14)+SUMIFS(WMS网点买断配件明细!I:I,WMS网点买断配件明细!K:K,$K$2,WMS网点买断配件明细!D:D,B14) -> 720 | L14: =SUMIFS(CSM配件!AB:AB,CSM配件!R:R,$L$2,CSM配件!D:D,B14)+SUMIFS(WMS网点买断配件明细!I:I,WMS网点买断配件明细!K:K,$L$2,WMS网点买断配件明细!D:D,B14) -> 0 | M14: =SUMIFS(CSM配件!AB:AB,CSM配件!R:R,$M$2,CSM配件!D:D,B14)+SUMIFS(WMS网点买断配件明细!I:I,WMS网点买断配件明细!K:K,$M$2,WMS网点买断配件明细!D:D,B14) -> 0 | N14: =SUMIFS(CSM配件!AB:AB,CSM配件!R:R,$N$2,CSM配件!D:D,B14)+SUMIFS(WMS网点买断配件明细!I:I,WMS网点买断配件明细!K:K,$N$2,WMS网点买断配件明细!D:D,B14) -> 0 | O14: =SUMIFS(CSM配件!AB:AB,CSM配件!R:R,$O$2,CSM配件!D:D,B14)+SUMIFS(WMS网点买断配件明细!I:I,WMS网点买断配件明细!K:K,$O$2,WMS网点买断配件明细!D:D,B14) -> 0 | P14: =SUMIFS(CSM配件!AB:AB,CSM配件!R:R,$P$2,CSM配件!D:D,B14)+SUMIFS(WMS网点买断配件明细!I:I,WMS网点买断配件明细!K:K,$P$2,WMS网点买断配件明细!D:D,B14) -> 0 | Q14: =SUM(C14:P14) -> 2196 | R14: =C14+D14+G14 -> 221
... A105: 新疆办事处 | B105: 伊宁边境经济合作区谢振升家电维修服务部 | C105: =SUMIFS(CSM服务项目!Y:Y,CSM服务项目!Q:Q,$C$2,CSM服务项目!D:D,B105) -> 150 | D105: =SUMIFS(CSM服务项目!Y:Y,CSM服务项目!Q:Q,$D$2,CSM服务项目!D:D,B105) -> 0 | E105: =SUMIFS(CSM配件!AB:AB,CSM配件!R:R,$E$2,CSM配件!D:D,B105) -> 1300 | F105: =SUMIFS(CSM配件!AB:AB,CSM配件!R:R,$F$2,CSM配件!D:D,B105) -> 0 | G105: =SUMIFS(CSM配件!AB:AB,CSM配件!R:R,$G$2,CSM配件!D:D,B105)+SUMIFS(WMS网点买断配件明细!I:I,WMS网点买断配件明细!K:K,$G$2,WMS网点买断配件明细!D:D,B105) -> 15 | H105: =SUMIFS(CSM配件!AB:AB,CSM配件!R:R,$H$2,CSM配件!D:D,B105)+SUMIFS(WMS网点买断配件明细!I:I,WMS网点买断配件明细!K:K,$H$2,WMS网点买断配件明细!D:D,B105) -> 0 | I105: =SUMIFS(CSM配件!AB:AB,CSM配件!R:R,$I$2,CSM配件!D:D,B105)+SUMIFS(WMS网点买断配件明细!I:I,WMS网点买断配件明细!K:K,$I$2,WMS网点买断配件明细!D:D,B105) -> 140 | J105: =SUMIFS(CSM配件!AB:AB,CSM配件!R:R,$J$2,CSM配件!D:D,B105)+SUMIFS(WMS网点买断配件明细!I:I,WMS网点买断配件明细!K:K,$J$2,WMS网点买断配件明细!D:D,B105) -> 175 | K105: =SUMIFS(CSM配件!AB:AB,CSM配件!R:R,$K$2,CSM配件!D:D,B105)+SUMIFS(WMS网点买断配件明细!I:I,WMS网点买断配件明细!K:K,$K$2,WMS网点买断配件明细!D:D,B105) -> 0 | L105: =SUMIFS(CSM配件!AB:AB,CSM配件!R:R,$L$2,CSM配件!D:D,B105)+SUMIFS(WMS网点买断配件明细!I:I,WMS网点买断配件明细!K:K,$L$2,WMS网点买断配件明细!D:D,B105) -> 0 | M105: =SUMIFS(CSM配件!AB:AB,CSM配件!R:R,$M$2,CSM配件!D:D,B105)+SUMIFS(WMS网点买断配件明细!I:I,WMS网点买断配件明细!K:K,$M$2,WMS网点买断配件明细!D:D,B105) -> 0 | N105: =SUMIFS(CSM配件!AB:AB,CSM配件!R:R,$N$2,CSM配件!D:D,B105)+SUMIFS(WMS网点买断配件明细!I:I,WMS网点买断配件明细!K:K,$N$2,WMS网点买断配件明细!D:D,B105) -> 0 | O105: =SUMIFS(CSM配件!AB:AB,CSM配件!R:R,$O$2,CSM配件!D:D,B105)+SUMIFS(WMS网点买断配件明细!I:I,WMS网点买断配件明细!K:K,$O$2,WMS网点买断配件明细!D:D,B105) -> 0 | P105: =SUMIFS(CSM配件!AB:AB,CSM配件!R:R,$P$2,CSM配件!D:D,B105)+SUMIFS(WMS网点买断配件明细!I:I,WMS网点买断配件明细!K:K,$P$2,WMS网点买断配件明细!D:D,B105) -> 0 | Q105: =SUM(C105:P105) -> 1780 | R105: =C105+D105+G105 -> 165

Sheet 技师数据
A1: 西北大区服务技师收入统计
A2: 办事处 | B2: 服务网点 | C2: 服务技师 | D2: 清洗保养 | E2: 延保服务 | F2: 止回阀 | G2: 装饰罩 | H2: 清洁耗材 | I2: 水/气路金属软管 | J2: 其他产品线专用 | K2: 排烟出风管 | L2: 其他水路辅材 | M2: 其他气路辅材 | N2: 橱柜类辅材 | O2: 水气路通用辅材 | P2: 燃气管快速接头 | Q2: 工具 | R2: 合计 | S2: 三大爆品合计 | T2: 任务 | U2: 完成进度 | V2: 烟机安装 | W2: 止回阀 | X2: 止回阀使用率
A3: 新疆办事处 | B3: 阿克苏市零壹家电维修部 | C3: 张蒙光 | D3: =SUMIFS(CSM服务项目!Y:Y,CSM服务项目!Q:Q,$D$2,CSM服务项目!F:F,C3) -> 0 | E3: =SUMIFS(CSM服务项目!Y:Y,CSM服务项目!Q:Q,$E$2,CSM服务项目!F:F,C3) -> 0 | F3: =SUMIFS(CSM配件!AB:AB,CSM配件!R:R,$F$2,CSM配件!F:F,C3) -> 800 | G3: =SUMIFS(CSM配件!AB:AB,CSM配件!R:R,$G$2,CSM配件!F:F,C3) -> 0 | H3: =SUMIFS(CSM配件!AB:AB,CSM配件!R:R,$H$2,CSM配件!F:F,C3) -> 0 | I3: =SUMIFS(CSM配件!AB:AB,CSM配件!R:R,$I$2,CSM配件!F:F,C3) -> 0 | J3: =SUMIFS(CSM配件!AB:AB,CSM配件!R:R,$J$2,CSM配件!F:F,C3) -> 98 | K3: =SUMIFS(CSM配件!AB:AB,CSM配件!R:R,$K$2,CSM配件!F:F,C3) -> 28 | L3: =SUMIFS(CSM配件!AB:AB,CSM配件!R:R,$L$2,CSM配件!F:F,C3) -> 0 | M3: =SUMIFS(CSM配件!AB:AB,CSM配件!R:R,$M$2,CSM配件!F:F,C3) -> 0 | N3: =SUMIFS(CSM配件!AB:AB,CSM配件!R:R,$N$2,CSM配件!F:F,C3) -> 0 | O3: =SUMIFS(CSM配件!AB:AB,CSM配件!R:R,$O$2,CSM配件!F:F,C3) -> 0 | P3: =SUMIFS(CSM配件!AB:AB,CSM配件!R:R,$P$2,CSM配件!F:F,C3) -> 0 | Q3: =SUMIFS(CSM配件!AB:AB,CSM配件!R:R,$Q$2,CSM配件!F:F,C3) -> 0 | R3: =SUM(D3:Q3) -> 926 | S3: =D3+E3+H3 -> 0 | V3: =COUNTIFS(工单!BV:BV,"吸油烟机",工单!BF:BF,"安装",工单!BD:BD,C3)+COUNTIFS(工单!BV:BV,"吸油烟机",工单!BF:BF,"改装",工单!BD:BD,C3)+COUNTIFS(工单!BV:BV,"吸油烟机",工单!BF:BF,"油烟机预埋烟管",工单!BD:BD,C3) -> 12 | W3: =COUNTIFS(CSM配件!R:R,$W$2,CSM配件!F:F,C3)+COUNTIFS(工单自购配件明细!N:N,"防火止回阀",工单自购配件明细!R:R,C3) -> 8 | X3: =W3/V3 -> 0.66666667
A4: 新疆办事处 | B4: 阿克苏市零壹家电维修部 | C4: 姚双全 | D4: =SUMIFS(CSM服务项目!Y:Y,CSM服务项目!Q:Q,$D$2,CSM服务项目!F:F,C4) -> 0 | E4: =SUMIFS(CSM服务项目!Y:Y,CSM服务项目!Q:Q,$E$2,CSM服务项目!F:F,C4) -> 0 | F4: =SUMIFS(CSM配件!AB:AB,CSM配件!R:R,$F$2,CSM配件!F:F,C4) -> 400 | G4: =SUMIFS(CSM配件!AB:AB,CSM配件!R:R,$G$2,CSM配件!F:F,C4) -> 0 | H4: =SUMIFS(CSM配件!AB:AB,CSM配件!R:R,$H$2,CSM配件!F:F,C4) -> 0 | I4: =SUMIFS(CSM配件!AB:AB,CSM配件!R:R,$I$2,CSM配件!F:F,C4) -> 0 | J4: =SUMIFS(CSM配件!AB:AB,CSM配件!R:R,$J$2,CSM配件!F:F,C4) -> 0 | K4: =SUMIFS(CSM配件!AB:AB,CSM配件!R:R,$K$2,CSM配件!F:F,C4) -> 0 | L4: =SUMIFS(CSM配件!AB:AB,CSM配件!R:R,$L$2,CSM配件!F:F,C4) -> 0 | M4: =SUMIFS(CSM配件!AB:AB,CSM配件!R:R,$M$2,CSM配件!F:F,C4) -> 0 | N4: =SUMIFS(CSM配件!AB:AB,CSM配件!R:R,$N$2,CSM配件!F:F,C4) -> 0 | O4: =SUMIFS(CSM配件!AB:AB,CSM配件!R:R,$O$2,CSM配件!F:F,C4) -> 0 | P4: =SUMIFS(CSM配件!AB:AB,CSM配件!R:R,$P$2,CSM配件!F:F,C4) -> 0 | Q4: =SUMIFS(CSM配件!AB:AB,CSM配件!R:R,$Q$2,CSM配件!F:F,C4) -> 0 | R4: =SUM(D4:Q4) -> 400 | S4: =D4+E4+H4 -> 0 | V4: =COUNTIFS(工单!BV:BV,"吸油烟机",工单!BF:BF,"安装",工单!BD:BD,C4)+COUNTIFS(工单!BV:BV,"吸油烟机",工单!BF:BF,"改装",工单!BD:BD,C4)+COUNTIFS(工单!BV:BV,"吸油烟机",工单!BF:BF,"油烟机预埋烟管",工单!BD:BD,C4) -> 2 | W4: =COUNTIFS(CSM配件!R:R,$W$2,CSM配件!F:F,C4)+COUNTIFS(工单自购配件明细!N:N,"防火止回阀",工单自购配件明细!R:R,C4) -> 4 | X4: =W4/V4 -> 2
A5: 新疆办事处 | B5: 北屯市安家厨房电器维修店（个体工商户） | C5: 赵灿明 | D5: =SUMIFS(CSM服务项目!Y:Y,CSM服务项目!Q:Q,$D$2,CSM服务项目!F:F,C5) -> 0 | E5: =SUMIFS(CSM服务项目!Y:Y,CSM服务项目!Q:Q,$E$2,CSM服务项目!F:F,C5) -> 1419.8 | F5: =SUMIFS(CSM配件!AB:AB,CSM配件!R:R,$F$2,CSM配件!F:F,C5) -> 100 | G5: =SUMIFS(CSM配件!AB:AB,CSM配件!R:R,$G$2,CSM配件!F:F,C5) -> 0 | H5: =SUMIFS(CSM配件!AB:AB,CSM配件!R:R,$H$2,CSM配件!F:F,C5) -> 0 | I5: =SUMIFS(CSM配件!AB:AB,CSM配件!R:R,$I$2,CSM配件!F:F,C5) -> 0 | J5: =SUMIFS(CSM配件!AB:AB,CSM配件!R:R,$J$2,CSM配件!F:F,C5) -> 105 | K5: =SUMIFS(CSM配件!AB:AB,CSM配件!R:R,$K$2,CSM配件!F:F,C5) -> 101.5 | L5: =SUMIFS(CSM配件!AB:AB,CSM配件!R:R,$L$2,CSM配件!F:F,C5) -> 0 | M5: =SUMIFS(CSM配件!AB:AB,CSM配件!R:R,$M$2,CSM配件!F:F,C5) -> 0 | N5: =SUMIFS(CSM配件!AB:AB,CSM配件!R:R,$N$2,CSM配件!F:F,C5) -> 0 | O5: =SUMIFS(CSM配件!AB:AB,CSM配件!R:R,$O$2,CSM配件!F:F,C5) -> 0 | P5: =SUMIFS(CSM配件!AB:AB,CSM配件!R:R,$P$2,CSM配件!F:F,C5) -> 0 | Q5: =SUMIFS(CSM配件!AB:AB,CSM配件!R:R,$Q$2,CSM配件!F:F,C5) -> 0 | R5: =SUM(D5:Q5) -> 1726.3 | S5: =D5+E5+H5 -> 1419.8 | V5: =COUNTIFS(工单!BV:BV,"吸油烟机",工单!BF:BF,"安装",工单!BD:BD,C5)+COUNTIFS(工单!BV:BV,"吸油烟机",工单!BF:BF,"改装",工单!BD:BD,C5)+COUNTIFS(工单!BV:BV,"吸油烟机",工单!BF:BF,"油烟机预埋烟管",工单!BD:BD,C5) -> 7 | W5: =COUNTIFS(CSM配件!R:R,$W$2,CSM配件!F:F,C5)+COUNTIFS(工单自购配件明细!N:N,"防火止回阀",工单自购配件明细!R:R,C5) -> 1 | X5: =W5/V5 -> 0.14285714
A6: 新疆办事处 | B6: 北屯市速达厨电安装中心 | C6: 王成良 | D6: =SUMIFS(CSM服务项目!Y:Y,CSM服务项目!Q:Q,$D$2,CSM服务项目!F:F,C6) -> 0 | E6: =SUMIFS(CSM服务项目!Y:Y,CSM服务项目!Q:Q,$E$2,CSM服务项目!F:F,C6) -> 0 | F6: =SUMIFS(CSM配件!AB:AB,CSM配件!R:R,$F$2,CSM配件!F:F,C6) -> 0 | G6: =SUMIFS(CSM配件!AB:AB,CSM配件!R:R,$G$2,CSM配件!F:F,C6) -> 0 | H6: =SUMIFS(CSM配件!AB:AB,CSM配件!R:R,$H$2,CSM配件!F:F,C6) -> 0 | I6: =SUMIFS(CSM配件!AB:AB,CSM配件!R:R,$I$2,CSM配件!F:F,C6) -> 0 | J6: =SUMIFS(CSM配件!AB:AB,CSM配件!R:R,$J$2,CSM配件!F:F,C6) -> 0 | K6: =SUMIFS(CSM配件!AB:AB,CSM配件!R:R,$K$2,CSM配件!F:F,C6) -> 0 | L6: =SUMIFS(CSM配件!AB:AB,CSM配件!R:R,$L$2,CSM配件!F:F,C6) -> 0 | M6: =SUMIFS(CSM配件!AB:AB,CSM配件!R:R,$M$2,CSM配件!F:F,C6) -> 0 | N6: =SUMIFS(CSM配件!AB:AB,CSM配件!R:R,$N$2,CSM配件!F:F,C6) -> 0 | O6: =SUMIFS(CSM配件!AB:AB,CSM配件!R:R,$O$2,CSM配件!F:F,C6) -> 0 | P6: =SUMIFS(CSM配件!AB:AB,CSM配件!R:R,$P$2,CSM配件!F:F,C6) -> 0 | Q6: =SUMIFS(CSM配件!AB:AB,CSM配件!R:R,$Q$2,CSM配件!F:F,C6) -> 0 | R6: =SUM(D6:Q6) -> 0 | S6: =D6+E6+H6 -> 0 | V6: =COUNTIFS(工单!BV:BV,"吸油烟机",工单!BF:BF,"安装",工单!BD:BD,C6)+COUNTIFS(工单!BV:BV,"吸油烟机",工单!BF:BF,"改装",工单!BD:BD,C6)+COUNTIFS(工单!BV:BV,"吸油烟机",工单!BF:BF,"油烟机预埋烟管",工单!BD:BD,C6) -> 0 | W6: =COUNTIFS(CSM配件!R:R,$W$2,CSM配件!F:F,C6)+COUNTIFS(工单自购配件明细!N:N,"防火止回阀",工单自购配件明细!R:R,C6) -> 0 | X6: =W6/V6 -> #DIV/0!
A7: 新疆办事处 | B7: 北屯市速达厨电安装中心 | C7: 杨继认 | D7: =SUMIFS(CSM服务项目!Y:Y,CSM服务项目!Q:Q,$D$2,CSM服务项目!F:F,C7) -> 0 | E7: =SUMIFS(CSM服务项目!Y:Y,CSM服务项目!Q:Q,$E$2,CSM服务项目!F:F,C7) -> 0 | F7: =SUMIFS(CSM配件!AB:AB,CSM配件!R:R,$F$2,CSM配件!F:F,C7) -> 0 | G7: =SUMIFS(CSM配件!AB:AB,CSM配件!R:R,$G$2,CSM配件!F:F,C7) -> 0 | H7: =SUMIFS(CSM配件!AB:AB,CSM配件!R:R,$H$2,CSM配件!F:F,C7) -> 0 | I7: =SUMIFS(CSM配件!AB:AB,CSM配件!R:R,$I$2,CSM配件!F:F,C7) -> 0 | J7: =SUMIFS(CSM配件!AB:AB,CSM配件!R:R,$J$2,CSM配件!F:F,C7) -> 0 | K7: =SUMIFS(CSM配件!AB:AB,CSM配件!R:R,$K$2,CSM配件!F:F,C7) -> 0 | L7: =SUMIFS(CSM配件!AB:AB,CSM配件!R:R,$L$2,CSM配件!F:F,C7) -> 0 | M7: =SUMIFS(CSM配件!AB:AB,CSM配件!R:R,$M$2,CSM配件!F:F,C7) -> 0 | N7: =SUMIFS(CSM配件!AB:AB,CSM配件!R:R,$N$2,CSM配件!F:F,C7) -> 0 | O7: =SUMIFS(CSM配件!AB:AB,CSM配件!R:R,$O$2,CSM配件!F:F,C7) -> 0 | P7: =SUMIFS(CSM配件!AB:AB,CSM配件!R:R,$P$2,CSM配件!F:F,C7) -> 0 | Q7: =SUMIFS(CSM配件!AB:AB,CSM配件!R:R,$Q$2,CSM配件!F:F,C7) -> 0 | R7: =SUM(D7:Q7) -> 0 | S7: =D7+E7+H7 -> 0 | V7: =COUNTIFS(工单!BV:BV,"吸油烟机",工单!BF:BF,"安装",工单!BD:BD,C7)+COUNTIFS(工单!BV:BV,"吸油烟机",工单!BF:BF,"改装",工单!BD:BD,C7)+COUNTIFS(工单!BV:BV,"吸油烟机",工单!BF:BF,"油烟机预埋烟管",工单!BD:BD,C7) -> 0 | W7: =COUNTIFS(CSM配件!R:R,$W$2,CSM配件!F:F,C7)+COUNTIFS(工单自购配件明细!N:N,"防火止回阀",工单自购配件明细!R:R,C7) -> 0 | X7: =W7/V7 -> #DIV/0!
A8: 新疆办事处 | B8: 北屯市王金女家电维修店 | C8: 古永洪 | D8: =SUMIFS(CSM服务项目!Y:Y,CSM服务项目!Q:Q,$D$2,CSM服务项目!F:F,C8) -> 1875 | E8: =SUMIFS(CSM服务项目!Y:Y,CSM服务项目!Q:Q,$E$2,CSM服务项目!F:F,C8) -> 0 | F8: =SUMIFS(CSM配件!AB:AB,CSM配件!R:R,$F$2,CSM配件!F:F,C8) -> 0 | G8: =SUMIFS(CSM配件!AB:AB,CSM配件!R:R,$G$2,CSM配件!F:F,C8) -> 0 | H8: =SUMIFS(CSM配件!AB:AB,CSM配件!R:R,$H$2,CSM配件!F:F,C8) -> 0 | I8: =SUMIFS(CSM配件!AB:AB,CSM配件!R:R,$I$2,CSM配件!F:F,C8) -> 0 | J8: =SUMIFS(CSM配件!AB:AB,CSM配件!R:R,$J$2,CSM配件!F:F,C8) -> 0 | K8: =SUMIFS(CSM配件!AB:AB,CSM配件!R:R,$K$2,CSM配件!F:F,C8) -> 0 | L8: =SUMIFS(CSM配件!AB:AB,CSM配件!R:R,$L$2,CSM配件!F:F,C8) -> 0 | M8: =SUMIFS(CSM配件!AB:AB,CSM配件!R:R,$M$2,CSM配件!F:F,C8) -> 0 | N8: =SUMIFS(CSM配件!AB:AB,CSM配件!R:R,$N$2,CSM配件!F:F,C8) -> 0 | O8: =SUMIFS(CSM配件!AB:AB,CSM配件!R:R,$O$2,CSM配件!F:F,C8) -> 0 | P8: =SUMIFS(CSM配件!AB:AB,CSM配件!R:R,$P$2,CSM配件!F:F,C8) -> 0 | Q8: =SUMIFS(CSM配件!AB:AB,CSM配件!R:R,$Q$2,CSM配件!F:F,C8) -> 0 | R8: =SUM(D8:Q8) -> 1875 | S8: =D8+E8+H8 -> 1875 | V8: =COUNTIFS(工单!BV:BV,"吸油烟机",工单!BF:BF,"安装",工单!BD:BD,C8)+COUNTIFS(工单!BV:BV,"吸油烟机",工单!BF:BF,"改装",工单!BD:BD,C8)+COUNTIFS(工单!BV:BV,"吸油烟机",工单!BF:BF,"油烟机预埋烟管",工单!BD:BD,C8) -> 0 | W8: =COUNTIFS(CSM配件!R:R,$W$2,CSM配件!F:F,C8)+COUNTIFS(工单自购配件明细!N:N,"防火止回阀",工单自购配件明细!R:R,C8) -> 0 | X8: =W8/V8 -> #DIV/0!
A9: 新疆办事处 | B9: 北屯市王金女家电维修店 | C9: 张喜珠 | D9: =SUMIFS(CSM服务项目!Y:Y,CSM服务项目!Q:Q,$D$2,CSM服务项目!F:F,C9) -> 100 | E9: =SUMIFS(CSM服务项目!Y:Y,CSM服务项目!Q:Q,$E$2,CSM服务项目!F:F,C9) -> 0 | F9: =SUMIFS(CSM配件!AB:AB,CSM配件!R:R,$F$2,CSM配件!F:F,C9) -> 100 | G9: =SUMIFS(CSM配件!AB:AB,CSM配件!R:R,$G$2,CSM配件!F:F,C9) -> 0 | H9: =SUMIFS(CSM配件!AB:AB,CSM配件!R:R,$H$2,CSM配件!F:F,C9) -> 380 | I9: =SUMIFS(CSM配件!AB:AB,CSM配件!R:R,$I$2,CSM配件!F:F,C9) -> 0 | J9: =SUMIFS(CSM配件!AB:AB,CSM配件!R:R,$J$2,CSM配件!F:F,C9) -> 35 | K9: =SUMIFS(CSM配件!AB:AB,CSM配件!R:R,$K$2,CSM配件!F:F,C9) -> 108.5 | L9: =SUMIFS(CSM配件!AB:AB,CSM配件!R:R,$L$2,CSM配件!F:F,C9) -> 28 | M9: =SUMIFS(CSM配件!AB:AB,CSM配件!R:R,$M$2,CSM配件!F:F,C9) -> 0 | N9: =SUMIFS(CSM配件!AB:AB,CSM配件!R:R,$N$2,CSM配件!F:F,C9) -> 0 | O9: =SUMIFS(CSM配件!AB:AB,CSM配件!R:R,$O$2,CSM配件!F:F,C9) -> 0 | P9: =SUMIFS(CSM配件!AB:AB,CSM配件!R:R,$P$2,CSM配件!F:F,C9) -> 0 | Q9: =SUMIFS(CSM配件!AB:AB,CSM配件!R:R,$Q$2,CSM配件!F:F,C9) -> 0 | R9: =SUM(D9:Q9) -> 751.5 | S9: =D9+E9+H9 -> 480 | V9: =COUNTIFS(工单!BV:BV,"吸油烟机",工单!BF:BF,"安装",工单!BD:BD,C9)+COUNTIFS(工单!BV:BV,"吸油烟机",工单!BF:BF,"改装",工单!BD:BD,C9)+COUNTIFS(工单!BV:BV,"吸油烟机",工单!BF:BF,"油烟机预埋烟管",工单!BD:BD,C9) -> 1 | W9: =COUNTIFS(CSM配件!R:R,$W$2,CSM配件!F:F,C9)+COUNTIFS(工单自购配件明细!N:N,"防火止回阀",工单自购配件明细!R:R,C9) -> 1 | X9: =W9/V9 -> 1
A10: 新疆办事处 | B10: 北屯市王金女家电维修店 | C10: 赵飞飞 | D10: =SUMIFS(CSM服务项目!Y:Y,CSM服务项目!Q:Q,$D$2,CSM服务项目!F:F,C10) -> 0 | E10: =SUMIFS(CSM服务项目!Y:Y,CSM服务项目!Q:Q,$E$2,CSM服务项目!F:F,C10) -> 0 | F10: =SUMIFS(CSM配件!AB:AB,CSM配件!R:R,$F$2,CSM配件!F:F,C10) -> 600 | G10: =SUMIFS(CSM配件!AB:AB,CSM配件!R:R,$G$2,CSM配件!F:F,C10) -> 0 | H10: =SUMIFS(CSM配件!AB:AB,CSM配件!R:R,$H$2,CSM配件!F:F,C10) -> 160 | I10: =SUMIFS(CSM配件!AB:AB,CSM配件!R:R,$I$2,CSM配件!F:F,C10) -> 0 | J10: =SUMIFS(CSM配件!AB:AB,CSM配件!R:R,$J$2,CSM配件!F:F,C10) -> 343 | K10: =SUMIFS(CSM配件!AB:AB,CSM配件!R:R,$K$2,CSM配件!F:F,C10) -> 28 | L10: =SUMIFS(CSM配件!AB:AB,CSM配件!R:R,$L$2,CSM配件!F:F,C10) -> 112 | M10: =SUMIFS(CSM配件!AB:AB,CSM配件!R:R,$M$2,CSM配件!F:F,C10) -> 0 | N10: =SUMIFS(CSM配件!AB:AB,CSM配件!R:R,$N$2,CSM配件!F:F,C10) -> 0 | O10: =SUMIFS(CSM配件!AB:AB,CSM配件!R:R,$O$2,CSM配件!F:F,C10) -> 0 | P10: =SUMIFS(CSM配件!AB:AB,CSM配件!R:R,$P$2,CSM配件!F:F,C10) -> 0 | Q10: =SUMIFS(CSM配件!AB:AB,CSM配件!R:R,$Q$2,CSM配件!F:F,C10) -> 0 | R10: =SUM(D10:Q10) -> 1243 | S10: =D10+E10+H10 -> 160 | V10: =COUNTIFS(工单!BV:BV,"吸油烟机",工单!BF:BF,"安装",工单!BD:BD,C10)+COUNTIFS(工单!BV:BV,"吸油烟机",工单!BF:BF,"改装",工单!BD:BD,C10)+COUNTIFS(工单!BV:BV,"吸油烟机",工单!BF:BF,"油烟机预埋烟管",工单!BD:BD,C10) -> 7 | W10: =COUNTIFS(CSM配件!R:R,$W$2,CSM配件!F:F,C10)+COUNTIFS(工单自购配件明细!N:N,"防火止回阀",工单自购配件明细!R:R,C10) -> 6 | X10: =W10/V10 -> 0.85714286
A11: 新疆办事处 | B11: 北屯市王金女家电维修店 | C11: 车攀宁 | D11: =SUMIFS(CSM服务项目!Y:Y,CSM服务项目!Q:Q,$D$2,CSM服务项目!F:F,C11) -> 0 | E11: =SUMIFS(CSM服务项目!Y:Y,CSM服务项目!Q:Q,$E$2,CSM服务项目!F:F,C11) -> 0 | F11: =SUMIFS(CSM配件!AB:AB,CSM配件!R:R,$F$2,CSM配件!F:F,C11) -> 700 | G11: =SUMIFS(CSM配件!AB:AB,CSM配件!R:R,$G$2,CSM配件!F:F,C11) -> 0 | H11: =SUMIFS(CSM配件!AB:AB,CSM配件!R:R,$H$2,CSM配件!F:F,C11) -> 0 | I11: =SUMIFS(CSM配件!AB:AB,CSM配件!R:R,$I$2,CSM配件!F:F,C11) -> 0 | J11: =SUMIFS(CSM配件!AB:AB,CSM配件!R:R,$J$2,CSM配件!F:F,C11) -> 245 | K11: =SUMIFS(CSM配件!AB:AB,CSM配件!R:R,$K$2,CSM配件!F:F,C11) -> 0 | L11: =SUMIFS(CSM配件!AB:AB,CSM配件!R:R,$L$2,CSM配件!F:F,C11) -> 56 | M11: =SUMIFS(CSM配件!AB:AB,CSM配件!R:R,$M$2,CSM配件!F:F,C11) -> 0 | N11: =SUMIFS(CSM配件!AB:AB,CSM配件!R:R,$N$2,CSM配件!F:F,C11) -> 59.5 | O11: =SUMIFS(CSM配件!AB:AB,CSM配件!R:R,$O$2,CSM配件!F:F,C11) -> 0 | P11: =SUMIFS(CSM配件!AB:AB,CSM配件!R:R,$P$2,CSM配件!F:F,C11) -> 0 | Q11: =SUMIFS(CSM配件!AB:AB,CSM配件!R:R,$Q$2,CSM配件!F:F,C11) -> 0 | R11: =SUM(D11:Q11) -> 1060.5 | S11: =D11+E11+H11 -> 0 | V11: =COUNTIFS(工单!BV:BV,"吸油烟机",工单!BF:BF,"安装",工单!BD:BD,C11)+COUNTIFS(工单!BV:BV,"吸油烟机",工单!BF:BF,"改装",工单!BD:BD,C11)+COUNTIFS(工单!BV:BV,"吸油烟机",工单!BF:BF,"油烟机预埋烟管",工单!BD:BD,C11) -> 6 | W11: =COUNTIFS(CSM配件!R:R,$W$2,CSM配件!F:F,C11)+COUNTIFS(工单自购配件明细!N:N,"防火止回阀",工单自购配件明细!R:R,C11) -> 7 | X11: =W11/V11 -> 1.1666667
A12: 新疆办事处 | B12: 北屯市王金女家电维修店 | C12: 王伟俊 | D12: =SUMIFS(CSM服务项目!Y:Y,CSM服务项目!Q:Q,$D$2,CSM服务项目!F:F,C12) -> 0 | E12: =SUMIFS(CSM服务项目!Y:Y,CSM服务项目!Q:Q,$E$2,CSM服务项目!F:F,C12) -> 389.3 | F12: =SUMIFS(CSM配件!AB:AB,CSM配件!R:R,$F$2,CSM配件!F:F,C12) -> 900 | G12: =SUMIFS(CSM配件!AB:AB,CSM配件!R:R,$G$2,CSM配件!F:F,C12) -> 0 | H12: =SUMIFS(CSM配件!AB:AB,CSM配件!R:R,$H$2,CSM配件!F:F,C12) -> 0 | I12: =SUMIFS(CSM配件!AB:AB,CSM配件!R:R,$I$2,CSM配件!F:F,C12) -> 0 | J12: =SUMIFS(CSM配件!AB:AB,CSM配件!R:R,$J$2,CSM配件!F:F,C12) -> 280 | K12: =SUMIFS(CSM配件!AB:AB,CSM配件!R:R,$K$2,CSM配件!F:F,C12) -> 203 | L12: =SUMIFS(CSM配件!AB:AB,CSM配件!R:R,$L$2,CSM配件!F:F,C12) -> 56 | M12: =SUMIFS(CSM配件!AB:AB,CSM配件!R:R,$M$2,CSM配件!F:F,C12) -> 0 | N12: =SUMIFS(CSM配件!AB:AB,CSM配件!R:R,$N$2,CSM配件!F:F,C12) -> 0 | O12: =SUMIFS(CSM配件!AB:AB,CSM配件!R:R,$O$2,CSM配件!F:F,C12) -> 0 | P12: =SUMIFS(CSM配件!AB:AB,CSM配件!R:R,$P$2,CSM配件!F:F,C12) -> 0 | Q12: =SUMIFS(CSM配件!AB:AB,CSM配件!R:R,$Q$2,CSM配件!F:F,C12) -> 0 | R12: =SUM(D12:Q12) -> 1828.3 | S12: =D12+E12+H12 -> 389.3 | V12: =COUNTIFS(工单!BV:BV,"吸油烟机",工单!BF:BF,"安装",工单!BD:BD,C12)+COUNTIFS(工单!BV:BV,"吸油烟机",工单!BF:BF,"改装",工单!BD:BD,C12)+COUNTIFS(工单!BV:BV,"吸油烟机",工单!BF:BF,"油烟机预埋烟管",工单!BD:BD,C12) -> 7 | W12: =COUNTIFS(CSM配件!R:R,$W$2,CSM配件!F:F,C12)+COUNTIFS(工单自购配件明细!N:N,"防火止回阀",工单自购配件明细!R:R,C12) -> 9 | X12: =W12/V12 -> 1.2857143
A13: 新疆办事处 | B13: 北屯市王金女家电维修店 | C13: 孟凡新 | D13: =SUMIFS(CSM服务项目!Y:Y,CSM服务项目!Q:Q,$D$2,CSM服务项目!F:F,C13) -> 0 | E13: =SUMIFS(CSM服务项目!Y:Y,CSM服务项目!Q:Q,$E$2,CSM服务项目!F:F,C13) -> 343.5 | F13: =SUMIFS(CSM配件!AB:AB,CSM配件!R:R,$F$2,CSM配件!F:F,C13) -> 400 | G13: =SUMIFS(CSM配件!AB:AB,CSM配件!R:R,$G$2,CSM配件!F:F,C13) -> 0 | H13: =SUMIFS(CSM配件!AB:AB,CSM配件!R:R,$H$2,CSM配件!F:F,C13) -> 0 | I13: =SUMIFS(CSM配件!AB:AB,CSM配件!R:R,$I$2,CSM配件!F:F,C13) -> 0 | J13: =SUMIFS(CSM配件!AB:AB,CSM配件!R:R,$J$2,CSM配件!F:F,C13) -> 245 | K13: =SUMIFS(CSM配件!AB:AB,CSM配件!R:R,$K$2,CSM配件!F:F,C13) -> 0 | L13: =SUMIFS(CSM配件!AB:AB,CSM配件!R:R,$L$2,CSM配件!F:F,C13) -> 56 | M13: =SUMIFS(CSM配件!AB:AB,CSM配件!R:R,$M$2,CSM配件!F:F,C13) -> 0 | N13: =SUMIFS(CSM配件!AB:AB,CSM配件!R:R,$N$2,CSM配件!F:F,C13) -> 0 | O13: =SUMIFS(CSM配件!AB:AB,CSM配件!R:R,$O$2,CSM配件!F:F,C13) -> 0 | P13: =SUMIFS(CSM配件!AB:AB,CSM配件!R:R,$P$2,CSM配件!F:F,C13) -> 0 | Q13: =SUMIFS(CSM配件!AB:AB,CSM配件!R:R,$Q$2,CSM配件!F:F,C13) -> 0 | R13: =SUM(D13:Q13) -> 1044.5 | S13: =D13+E13+H13 -> 343.5 | V13: =COUNTIFS(工单!BV:BV,"吸油烟机",工单!BF:BF,"安装",工单!BD:BD,C13)+COUNTIFS(工单!BV:BV,"吸油烟机",工单!BF:BF,"改装",工单!BD:BD,C13)+COUNTIFS(工单!BV:BV,"吸油烟机",工单!BF:BF,"油烟机预埋烟管",工单!BD:BD,C13) -> 3 | W13: =COUNTIFS(CSM配件!R:R,$W$2,CSM配件!F:F,C13)+COUNTIFS(工单自购配件明细!N:N,"防火止回阀",工单自购配件明细!R:R,C13) -> 4 | X13: =W13/V13 -> 1.3333333
A14: 新疆办事处 | B14: 北屯市王金女家电维修店 | C14: 王立辉 | D14: =SUMIFS(CSM服务项目!Y:Y,CSM服务项目!Q:Q,$D$2,CSM服务项目!F:F,C14) -> 0 | E14: =SUMIFS(CSM服务项目!Y:Y,CSM服务项目!Q:Q,$E$2,CSM服务项目!F:F,C14) -> 0 | F14: =SUMIFS(CSM配件!AB:AB,CSM配件!R:R,$F$2,CSM配件!F:F,C14) -> 300 | G14: =SUMIFS(CSM配件!AB:AB,CSM配件!R:R,$G$2,CSM配件!F:F,C14) -> 0 | H14: =SUMIFS(CSM配件!AB:AB,CSM配件!R:R,$H$2,CSM配件!F:F,C14) -> 0 | I14: =SUMIFS(CSM配件!AB:AB,CSM配件!R:R,$I$2,CSM配件!F:F,C14) -> 0 | J14: =SUMIFS(CSM配件!AB:AB,CSM配件!R:R,$J$2,CSM配件!F:F,C14) -> 140 | K14: =SUMIFS(CSM配件!AB:AB,CSM配件!R:R,$K$2,CSM配件!F:F,C14) -> 206.5 | L14: =SUMIFS(CSM配件!AB:AB,CSM配件!R:R,$L$2,CSM配件!F:F,C14) -> 0 | M14: =SUMIFS(CSM配件!AB:AB,CSM配件!R:R,$M$2,CSM配件!F:F,C14) -> 0 | N14: =SUMIFS(CSM配件!AB:AB,CSM配件!R:R,$N$2,CSM配件!F:F,C14) -> 0 | O14: =SUMIFS(CSM配件!AB:AB,CSM配件!R:R,$O$2,CSM配件!F:F,C14) -> 0 | P14: =SUMIFS(CSM配件!AB:AB,CSM配件!R:R,$P$2,CSM配件!F:F,C14) -> 0 | Q14: =SUMIFS(CSM配件!AB:AB,CSM配件!R:R,$Q$2,CSM配件!F:F,C14) -> 0 | R14: =SUM(D14:Q14) -> 646.5 | S14: =D14+E14+H14 -> 0 | V14: =COUNTIFS(工单!BV:BV,"吸油烟机",工单!BF:BF,"安装",工单!BD:BD,C14)+COUNTIFS(工单!BV:BV,"吸油烟机",工单!BF:BF,"改装",工单!BD:BD,C14)+COUNTIFS(工单!BV:BV,"吸油烟机",工单!BF:BF,"油烟机预埋烟管",工单!BD:BD,C14) -> 4 | W14: =COUNTIFS(CSM配件!R:R,$W$2,CSM配件!F:F,C14)+COUNTIFS(工单自购配件明细!N:N,"防火止回阀",工单自购配件明细!R:R,C14) -> 3 | X14: =W14/V14 -> 0.75
... A281: 包头办事处 | B281: 伊金霍洛旗刘庆春电器店 | C281: 李勇 | D281: =SUMIFS(CSM服务项目!Y:Y,CSM服务项目!Q:Q,$D$2,CSM服务项目!F:F,C281) -> 0 | E281: =SUMIFS(CSM服务项目!Y:Y,CSM服务项目!Q:Q,$E$2,CSM服务项目!F:F,C281) -> 0 | F281: =SUMIFS(CSM配件!AB:AB,CSM配件!R:R,$F$2,CSM配件!F:F,C281) -> 100 | G281: =SUMIFS(CSM配件!AB:AB,CSM配件!R:R,$G$2,CSM配件!F:F,C281) -> 0 | H281: =SUMIFS(CSM配件!AB:AB,CSM配件!R:R,$H$2,CSM配件!F:F,C281) -> 0 | I281: =SUMIFS(CSM配件!AB:AB,CSM配件!R:R,$I$2,CSM配件!F:F,C281) -> 0 | J281: =SUMIFS(CSM配件!AB:AB,CSM配件!R:R,$J$2,CSM配件!F:F,C281) -> 280 | K281: =SUMIFS(CSM配件!AB:AB,CSM配件!R:R,$K$2,CSM配件!F:F,C281) -> 35 | L281: =SUMIFS(CSM配件!AB:AB,CSM配件!R:R,$L$2,CSM配件!F:F,C281) -> 0 | M281: =SUMIFS(CSM配件!AB:AB,CSM配件!R:R,$M$2,CSM配件!F:F,C281) -> 0 | N281: =SUMIFS(CSM配件!AB:AB,CSM配件!R:R,$N$2,CSM配件!F:F,C281) -> 0 | O281: =SUMIFS(CSM配件!AB:AB,CSM配件!R:R,$O$2,CSM配件!F:F,C281) -> 0 | P281: =SUMIFS(CSM配件!AB:AB,CSM配件!R:R,$P$2,CSM配件!F:F,C281) -> 0 | Q281: =SUMIFS(CSM配件!AB:AB,CSM配件!R:R,$Q$2,CSM配件!F:F,C281) -> 0 | R281: =SUM(D281:Q281) -> 415 | S281: =D281+E281+H281 -> 0 | V281: =COUNTIFS(工单!BV:BV,"吸油烟机",工单!BF:BF,"安装",工单!BD:BD,C281)+COUNTIFS(工单!BV:BV,"吸油烟机",工单!BF:BF,"改装",工单!BD:BD,C281)+COUNTIFS(工单!BV:BV,"吸油烟机",工单!BF:BF,"油烟机预埋烟管",工单!BD:BD,C281) -> 11 | W281: =COUNTIFS(CSM配件!R:R,$W$2,CSM配件!F:F,C281)+COUNTIFS(工单自购配件明细!N:N,"防火止回阀",工单自购配件明细!R:R,C281) -> 1 | X281: =W281/V281 -> 0.090909091

Sheet WMS网点买断配件明细
A1: WMS网点买断配件明细
A2: 大区 | B2: 办事处名称 | C2: 所属服务中心 | D2: CSM网点名称 | E2: 订单号 | F2: 配件编码 | G2: 配件名称 | H2: 数量 | I2: 实收总金额（上缴金额） | J2: 配件分类 | K2: 销售分类 | L2: 发货时间 | M2: 传输时间
A3: 西北大区部 | B3: 包头办事处 | C3: 包头服务中心 | D3: 青山区厨小帮家电维修门店 | E3: CK20260805000071 | F3: 1506040100586 | G3: 洗碗机专用盐-2KG/瓶-/ | H3: 4 | I3: 60 | J3: H | K3: 清洁耗材 | L3: 46242.521 | M3: 2026-08-08 23:00:01
A4: 西北大区部 | B4: 包头办事处 | C4: 包头服务中心 | D4: 青山区厨小帮家电维修门店 | E4: CK20260805000071 | F4: 1507020201567 | G4: 快速接头(螺纹)-RBG-S10×15-GB/T26002-WJ(2025) | H4: 10 | I4: 44.4 | J4: H | K4: 燃气管快速接头 | L4: 46242.521 | M4: 2026-08-08 23:00:01
A5: 西北大区部 | B5: 包头办事处 | C5: 包头服务中心 | D5: 青山区厨小帮家电维修门店 | E5: CK20260805000071 | F5: 1507020201554 | G5: 不锈钢波纹软管-RSB-10-GB/T26002-30m-WJ(2025) | H5: 1 | I5: 408.21 | J5: H | K5: 水/气路金属软管 | L5: 46242.521 | M5: 2026-08-08 23:00:01
A6: 西北大区部 | B6: 包头办事处 | C6: 包头服务中心 | D6: 青山区厨小帮家电维修门店 | E6: CK20260806000119 | F6: 1506040100619 | G6: 锅支架清洁膏(正式装)-250g膏体-/ | H6: 24 | I6: 384 | J6: B | K6: 清洁耗材 | L6: 46242.52 | M6: 2026-08-08 14:00:01
A7: 西北大区部 | B7: 兰州办事处 | C7: 兰州服务中心 | D7: 西峰区二牛电器维修服务中心 | E7: CK20260805000054 | F7: 1507020201554 | G7: 不锈钢波纹软管-RSB-10-GB/T26002-30m-WJ(2025) | H7: 3 | I7: 1224.63 | J7: H | K7: 水/气路金属软管 | L7: 46239.677 | M7: 2026-08-05 23:00:07
A8: 西北大区部 | B8: 兰州办事处 | C8: 兰州服务中心 | D8: 天水晨旺家电服务有限公司 | E8: CK20260805000051 | F8: 1507020201569 | G8: 快速接头(螺纹)-RBG-S13×15-GB/T26002-WJ(2025) | H8: 200 | I8: 1004 | J8: H | K8: 燃气管快速接头 | L8: 46239.676 | M8: 2026-08-05 23:00:08
A9: 西北大区部 | B9: 兰州办事处 | C9: 兰州服务中心 | D9: 天水晨旺家电服务有限公司 | E9: CK20260805000051 | F9: 1507020201557 | G9: 不锈钢波纹软管-RSB-13-GB/T26002-30m-WJ(2025) | H9: 8 | I9: 3702.24 | J9: H | K9: 水/气路金属软管 | L9: 46239.676 | M9: 2026-08-05 23:00:08
A10: 西北大区部 | B10: 兰州办事处 | C10: 兰州服务中心 | D10: 武都百佳润电器维修服务中心 | E10: CK20260805000050 | F10: 1507020201557 | G10: 不锈钢波纹软管-RSB-13-GB/T26002-30m-WJ(2025) | H10: 1 | I10: 462.78 | J10: H | K10: 水/气路金属软管 | L10: 46239.665 | M10: 2026-08-05 23:00:07
A11: 西北大区部 | B11: 兰州办事处 | C11: 兰州服务中心 | D11: 永登鑫元家电维修部（个体工商户） | E11: CK20260804000014 | F11: 1507020201554 | G11: 不锈钢波纹软管-RSB-10-GB/T26002-30m-WJ(2025) | H11: 5 | I11: 2041.05 | J11: H | K11: 水/气路金属软管 | L11: 46238.431 | M11: 2026-08-04 23:00:04
A12: 西北大区部 | B12: 西宁办事处 | C12: 兰州服务中心 | D12: 西宁广仁技术服务有限公司 | E12: CK20260729000093 | F12: 1506040100577 | G12: 蒸烤产品油污清洗套装-500ml-/ | H12: 1 | I12: 40 | J12: H | K12: 清洁耗材 | L12: 46232.686
A13: 西北大区部 | B13: 新疆办事处 | C13: 乌鲁木齐服务中心 | D13: 昌吉市井清家电维修服务部 | E13: CK20260805000031 | F13: 1507020201554 | G13: 不锈钢波纹软管-RSB-10-GB/T26002-30m-WJ(2025) | H13: 10 | I13: 4082.1 | J13: H | K13: 水/气路金属软管 | L13: 46239.451 | M13: 2026-08-05 23:00:06
A14: 西北大区部 | B14: 新疆办事处 | C14: 乌鲁木齐服务中心 | D14: 库尔勒泽玉家电维修服务中心（个体工商户） | E14: CK20260806000104 | F14: 1507020201567 | G14: 快速接头(螺纹)-RBG-S10×15-GB/T26002-WJ(2025) | H14: 50 | I14: 222 | J14: H | K14: 燃气管快速接头 | L14: 46240.761 | M14: 2026-08-06 23:00:05
A15: 西北大区部 | B15: 新疆办事处 | C15: 乌鲁木齐服务中心 | D15: 库尔勒泽玉家电维修服务中心（个体工商户） | E15: CK20260806000104 | F15: 1507020201554 | G15: 不锈钢波纹软管-RSB-10-GB/T26002-30m-WJ(2025) | H15: 1 | I15: 408.21 | J15: H | K15: 水/气路金属软管 | L15: 46240.761 | M15: 2026-08-06 23:00:05
A16: 西北大区部 | B16: 新疆办事处 | C16: 乌鲁木齐服务中心 | D16: 库尔勒远祥家电维修部 | E16: CK20260806000103 | F16: 1507020201567 | G16: 快速接头(螺纹)-RBG-S10×15-GB/T26002-WJ(2025) | H16: 50 | I16: 222 | J16: H | K16: 燃气管快速接头 | L16: 46240.738 | M16: 2026-08-06 23:00:04
A17: 西北大区部 | B17: 新疆办事处 | C17: 乌鲁木齐服务中心 | D17: 库尔勒远祥家电维修部 | E17: CK20260806000103 | F17: 1507020201554 | G17: 不锈钢波纹软管-RSB-10-GB/T26002-30m-WJ(2025) | H17: 1 | I17: 408.21 | J17: H | K17: 水/气路金属软管 | L17: 46240.738 | M17: 2026-08-06 23:00:04
A18: 西北大区部 | B18: 新疆办事处 | C18: 乌鲁木齐服务中心 | D18: 阿克苏市零壹家电维修部 | E18: CK20260806000099 | F18: 1507020201554 | G18: 不锈钢波纹软管-RSB-10-GB/T26002-30m-WJ(2025) | H18: 2 | I18: 816.42 | J18: H | K18: 水/气路金属软管 | L18: 46240.713 | M18: 2026-08-06 23:00:04
A19: 西北大区部 | B19: 新疆办事处 | C19: 乌鲁木齐服务中心 | D19: 阿克苏市零壹家电维修部 | E19: CK20260806000099 | F19: 1507020201567 | G19: 快速接头(螺纹)-RBG-S10×15-GB/T26002-WJ(2025) | H19: 50 | I19: 222 | J19: H | K19: 燃气管快速接头 | L19: 46240.713 | M19: 2026-08-06 23:00:04
A20: 西北大区部 | B20: 新疆办事处 | C20: 乌鲁木齐服务中心 | D20: 昌吉市井清家电维修服务部 | E20: CK20260806000097 | F20: 1507020201566 | G20: 快速接头(插口)-RBG-S10×Φ9.5-GB/T26002-WJ(2025) | H20: 100 | I20: 907 | J20: H | K20: 燃气管快速接头 | L20: 46240.708 | M20: 2026-08-06 23:00:04
